Workbook

Sheet résultats
B5: Trial | C5: Edge | D5: NC | E5: N av | F5: N max | G5: Fpav | H5: Fpmax | I5: Fs av | J5: Fs max | K5: Fpnav | L5: Fpn max | M5: P av | N5: P max | O5: Fz av | P5: Fz max | Q5: R av | R5: R max | S5: AEA av | T5: AEA max | U5: λ av | V5: λ max | W5: η | X5: μe | Y5: β | Z5: VB max | AA5: VB av | AB5: Rt | AC5: Ra | AD5: Curve
B6: N° | C6: ref | D6: rev | E6: N | F6: N | G6: N | H6: N | I6: N | J6: N | K6: N | L6: N | M6: N | N6: N | O6: N | P6: N | Q6: N | R6: N | S6: ° | T6: ° | U6: ° | V6: ° | W6: ° | Y6: ° | Z6: µm | AA6: µm | AB6: µm | AC6: µm | AD6: µm
A7: Results | B7: 1 | C7: 0244E3 | D7: 9402 | E7: 383.19 | F7: 974.4 | G7: 557.23 | H7: 1042.73 | I7: 682.28 | J7: 1413.81 | K7: -173.65 | L7: -459.85 | M7: 587.54 | N7: 1083.94 | O7: 123.81 | P7: 240.99 | Q7: 707.71 | R7: 1453.91 | S7: 79.73 | T7: 83.64 | U7: 15.96 | V7: 20.16 | W7: 68.82 | X7: =ATAN(Y7) -> 1.5547669 | Y7: 62.38 | Z7: 16 | AA7: 14.33
C8: 0374E4 | D8: 9402 | E8: 362.63 | F8: 928.26 | G8: 561.36 | H8: 980.33 | I8: 675 | J8: 1344.96 | K8: -168.47 | L8: -376.24 | M8: 587.52 | N8: 1028.3 | O8: 137.04 | P8: 220.23 | Q8: 697.11 | R8: 1385.31 | S8: 76.05 | T8: 82.35 | U8: 12.98 | V8: 14.89 | W8: 74.88 | X8: =ATAN(Y8) -> 1.5543477 | Y8: 60.79 | Z8: 16 | AA8: 13.33
C9: 0533E2 | D9: 9402 | E9: 370.48 | F9: 910.95 | G9: 564.16 | H9: 975.76 | I9: 681.55 | J9: 1334.89 | K9: -169.35 | L9: -333.09 | M9: 590.37 | N9: 1016.65 | O9: 135.62 | P9: 219.74 | Q9: 703.79 | R9: 1365.07 | S9: 78.59 | T9: 83.72 | U9: 18.98 | V9: 22.54 | W9: 68.83 | X9: =ATAN(Y9) -> 1.5554648 | Y9: 65.22 | Z9: 15 | AA9: 13.67 | AE9: -
B10: 2 | C10: 0244E3 | D10: =D7*2 -> 18804 | E10: 355.14 | F10: 979.89 | G10: 499.01 | H10: 1037.58 | I10: 618 | J10: 1404.19 | K10: -152.95 | L10: -429.02 | M10: 525.36 | N10: 1083.88 | O10: 108.48 | P10: 234.79 | Q10: 640.03 | R10: 1438.73 | S10: 79.91 | T10: 82.59 | U10: 16.17 | V10: 20.27 | W10: 70.99 | X10: =ATAN(Y10) -> 1.5515975 | Y10: 52.08 | Z10: 18 | AA10: 16.67
C11: 0374E4 | D11: 18804 | E11: 418.09 | F11: 945.37 | G11: 608.46 | H11: 1021.73 | I11: 743.6 | J11: 1385.42 | K11: -178.69 | L11: -377.64 | M11: 635.96 | N11: 1067.54 | O11: 142.57 | P11: 232.98 | Q11: 766.56 | R11: 1419.81 | S11: 75.06 | T11: 78.45 | U11: 10.65 | V11: 13.1 | W11: 77.52 | X11: =ATAN(Y11) -> 1.5539089 | Y11: 59.21 | Z11: 29 | AA11: 25.67
C12: 0533E2 | D12: 18804 | E12: 393.26 | F12: 805.24 | G12: 576.45 | H12: 900.5 | I12: 703.83 | J12: 1204.85 | K12: -148.76 | L12: -281.77 | M12: 596.1 | N12: 935.82 | O12: 149.68 | P12: 214.52 | Q12: 720.2 | R12: 1225.64 | S12: 76.2 | T12: 81.18 | U12: 13.42 | V12: 15.38 | W12: 74.48 | X12: =ATAN(Y12) -> 1.5544312 | Y12: 61.1 | Z12: 17 | AA12: 14 | AE12: -
B13: 3 | C13: 0244E3 | D13: =D7*3 -> 28206 | E13: 376.67 | F13: 908.1 | G13: 525.96 | H13: 926.45 | I13: 653.23 | J13: 1297.28 | K13: -160.55 | L13: -363.42 | M13: 551.6 | N13: 964.64 | O13: 113.98 | P13: 187.57 | Q13: 674.63 | R13: 1324.83 | S13: 79.49 | T13: 83.17 | U13: 15.01 | V13: 20.33 | W13: 75.39 | X13: =ATAN(Y13) -> 1.5514601 | Y13: 51.71 | Z13: 22 | AA13: 19
C14: 0374E4 | D14: 28206 | E14: 379.27 | F14: 958.16 | G14: 590 | H14: 1026.63 | I14: 708.21 | J14: 1398.75 | K14: -170.41 | L14: -392.93 | M14: 615.28 | N14: 1077.48 | O14: 149.09 | P14: 226.55 | Q14: 729.61 | R14: 1436.48 | S14: 77.76 | T14: 80.15 | U14: 14.13 | V14: 18.68 | W14: 73.55 | X14: =ATAN(Y14) -> 1.5540587 | Y14: 59.74 | Z14: 28 | AA14: 22.33
C15: 0533E2 | D15: 28206 | E15: 389.46 | F15: 878.01 | G15: 609.62 | H15: 1029.42 | I15: 730.22 | J15: 1419.93 | K15: -182.78 | L15: -415.38 | M15: 637.59 | N15: 1089.74 | O15: 150.42 | P15: 204.95 | Q15: 753.95 | R15: 1464.25 | S15: 76.7 | T15: 84.61 | U15: 14.17 | V15: 16.43 | W15: 73.57 | X15: =ATAN(Y15) -> 1.5545482 | Y15: 61.54 | Z15: 20 | AA15: 17.33 | AE15: -
B16: 4 | C16: 0244E3 | D16: =D7*4 -> 37608 | E16: 373.15 | F16: 972.98 | G16: 525.28 | H16: 983.85 | I16: 650.46 | J16: 1383.71 | K16: -161.2 | L16: -377.87 | M16: 551.6 | N16: 1030.64 | O16: 114.29 | P16: 172.85 | Q16: 672.4 | R16: 1417.36 | S16: 76.84 | T16: 80.76 | U16: 10.29 | V16: 11.8 | W16: 77.44 | X16: =ATAN(Y16) -> 1.5529475 | Y16: 56.02 | Z16: 23 | AA16: 21
C17: 0374E4 | D17: 37608 | E17: 372.82 | F17: 964.16 | G17: 598.2 | H17: 1038.62 | I17: 711.69 | J17: 1412.85 | K17: -172.61 | L17: -417.45 | M17: 623.93 | N17: 1088.82 | O17: 155.28 | P17: 221.62 | Q17: 733.69 | R17: 1454.35 | S17: 77.5 | T17: 83.11 | U17: 15.89 | V17: 17.81 | W17: 71.87 | X17: =ATAN(Y17) -> 1.5547823 | Y17: 62.44 | Z17: 38 | AA17: 30
C18: 0533E2 | D18: 37608 | E18: 391.44 | F18: 991.22 | G18: 609.16 | H18: 1096.06 | I18: 730.28 | J18: 1473.25 | K18: -181.65 | L18: -401.44 | M18: 637.01 | N18: 1149.57 | O18: 150.18 | P18: 239.33 | Q18: 753.93 | R18: 1513.48 | S18: 77.17 | T18: 79.25 | U18: 15.4 | V18: 18.49 | W18: 72.54 | X18: =ATAN(Y18) -> 1.5547309 | Y18: 62.24 | Z18: 26 | AA18: 22 | AE18: -
B19: 5 | C19: 0244E3 | D19: =D7*5 -> 47010 | E19: 362.95 | F19: 879.52 | G19: 518.2 | H19: 867.54 | I19: 638 | J19: 1256.64 | K19: -157.82 | L19: -340.6 | M19: 543.13 | N19: 937.91 | O19: 115.33 | P19: 174.56 | Q19: 658.81 | R19: 1285.78 | S19: 79.51 | T19: 81.83 | U19: 15.15 | V19: 18.76 | W19: 72.07 | X19: =ATAN(Y19) -> 1.5536336 | Y19: 58.26 | Z19: 27 | AA19: 24.33
C20: 0374E4 | D20: 47010 | E20: 362.8 | F20: 932.71 | G20: 581.55 | H20: 1043.53 | I20: 691.7 | J20: 1393.07 | K20: -163 | L20: -395.56 | M20: 605.42 | N20: 1086.35 | O20: 154.03 | P20: 213.48 | Q20: 712.1 | R20: 1431.68 | S20: 75.36 | T20: 80.65 | U20: 10.74 | V20: 11.58 | W20: 77.3 | X20: =ATAN(Y20) -> 1.5538171 | Y20: 58.89 | Z20: 41 | AA20: 32.33
C21: 0533E2 | D21: 47010 | E21: 417.85 | F21: 994.14 | G21: 643.68 | H21: 1059.68 | I21: 773.17 | J21: 1439.74 | K21: -193.8 | L21: -413.3 | M21: 674.24 | N21: 1107.07 | O21: 156.02 | P21: 243.74 | Q21: 799.15 | R21: 1478.45 | S21: 76.83 | T21: 77.82 | U21: 15.26 | V21: 18.36 | W21: 72.79 | X21: =ATAN(Y21) -> 1.5548181 | Y21: 62.58 | Z21: 30 | AA21: 24.67 | AE21: -
B22: 6 | C22: 0244E3 | D22: =D7*6 -> 56412 | E22: 358.71 | F22: 920.97 | G22: 514.18 | H22: 894.24 | I22: 632.35 | J22: 1283.69 | K22: -156.96 | L22: -353.45 | M22: 539.64 | N22: 939.05 | O22: 114.68 | P22: 192.5 | Q22: 653.65 | R22: 1315.3 | S22: 79.79 | T22: 83.47 | U22: 17.48 | V22: 19.31 | W22: 69.79 | X22: =ATAN(Y22) -> 1.554399 | Y22: 60.98 | Z22: 35 | AA22: 29.67
C23: 0374E4 | D23: 56412 | E23: 372.97 | F23: 795.18 | G23: 566.73 | H23: 881.17 | I23: 685.17 | J23: 1186.92 | K23: -143.51 | L23: -279.94 | M23: 585.42 | N23: 907.17 | O23: 153.65 | P23: 217.67 | Q23: 700.89 | R23: 1206.34 | S23: 75.45 | T23: 79.6 | U23: 8.55 | V23: 9.58 | W23: 79.58 | X23: =ATAN(Y23) -> 1.5529634 | Y23: 56.07 | Z23: 42 | AA23: 35.33
C24: 0533E2 | D24: 56412 | E24: 373.72 | F24: 1013.63 | G24: 615.53 | H24: 1079.01 | I24: 729.25 | J24: 1480.45 | K24: -191.7 | L24: -499.4 | M24: 651.02 | N24: 1156.91 | O24: 153.8 | P24: 332.87 | Q24: 758.98 | R24: 1534.89 | S24: 77.56 | T24: 81.21 | U24: 15.13 | V24: 15.65 | W24: 72.58 | X24: =ATAN(Y24) -> 1.5544312 | Y24: 61.1 | Z24: 20 | AA24: 16 | AE24: -
B25: 7 | C25: 0244E3 | D25: =D7*7 -> 65814 | E25: 360.17 | F25: 882.62 | G25: 514.62 | H25: 881.85 | I25: 634.35 | J25: 1247.67 | K25: -156.48 | L25: -327.95 | M25: 539.59 | N25: 915.84 | O25: 114.78 | P25: 181.21 | Q25: 655.14 | R25: 1271.92 | S25: 77.33 | T25: 79.93 | U25: 11.19 | V25: 12.42 | W25: 76.5 | X25: =ATAN(Y25) -> 1.5530614 | Y25: 56.38 | Z25: 53 | AA25: 40.67
C26: 0374E4 | D26: 65814 | E26: 355.23 | F26: 957.85 | G26: 592.23 | H26: 1034.11 | I26: 699.24 | J26: 1401.27 | K26: -166.17 | L26: -393.72 | M26: 616.6 | N26: 1083.92 | O26: 161.6 | P26: 254.83 | Q26: 720.11 | R26: 1440.7 | S26: 74.55 | T26: 79.21 | U26: 11.07 | V26: 12.54 | W26: 77.18 | X26: =ATAN(Y26) -> 1.5542716 | Y26: 60.51 | Z26: 45 | AA26: 37
C27: 0533E2 | D27: 65814 | E27: 346.19 | F27: 988.07 | G27: 535.35 | H27: 1035.01 | I27: 645.01 | J27: 1418.54 | K27: -145.19 | L27: -418.56 | M27: 559.97 | N27: 1084.27 | O27: 140.84 | P27: 266.71 | Q27: 665.16 | R27: 1466.95 | S27: 75.62 | T27: 80.76 | U27: 10.93 | V27: 12.5 | W27: 77.08 | X27: =ATAN(Y27) -> 1.5537331 | Y27: 58.6 | Z27: 24 | AA27: 23 | AE27: -
B28: 8 | C28: 0244E3 | D28: =D7*8 -> 75216 | E28: 352.94 | F28: 862.35 | G28: 517.83 | H28: 881.46 | I28: 631.93 | J28: 1233.13 | K28: -155.71 | L28: -319.86 | M28: 542.3 | N28: 922.91 | O28: 119.9 | P28: 176.8 | Q28: 652.49 | R28: 1263.09 | S28: 77.84 | T28: 81.98 | U28: 10.14 | V28: 11.34 | W28: 77.41 | X28: =ATAN(Y28) -> 1.5524262 | Y28: 54.43 | Z28: 56 | AA28: 46
C29: 0374E4 | D29: 75216 | E29: 366.15 | F29: 980.66 | G29: 611.41 | H29: 1069.28 | I29: 721.41 | J29: 1450.88 | K29: -170.85 | L29: -418.6 | M29: 636.22 | N29: 1122.47 | O29: 167.5 | P29: 233.17 | Q29: 742.67 | R29: 1490.51 | S29: 73.33 | T29: 79.52 | U29: 11.04 | V29: 12.67 | W29: 77.33 | X29: =ATAN(Y29) -> 1.5547823 | Y29: 62.44 | Z29: 50 | AA29: 42
C30: 0533E2 | D30: 75216 | E30: 382.45 | F30: 966.46 | G30: 598.35 | H30: 1001.26 | I30: 718.05 | J30: 1391.6 | K30: -180.36 | L30: -361.37 | M30: 627.16 | N30: 1048.42 | O30: 146.93 | P30: 246.11 | Q30: 742.17 | R30: 1425.91 | S30: 75.79 | T30: 80.13 | U30: 13.17 | V30: 15.11 | W30: 74.92 | X30: =ATAN(Y30) -> 1.5544846 | Y30: 61.3 | Z30: 30 | AA30: 25.67 | AE30: -
B31: 9 | C31: 0244E3 | D31: =D7*9 -> 84618 | E31: 378.28 | F31: 896.61 | G31: 546.62 | H31: 930.71 | I31: 672.04 | J31: 1292.34 | K31: -166.33 | L31: -379.25 | M31: 572.66 | N31: 963.64 | O31: 123.3 | P31: 206.74 | Q31: 693.88 | R31: 1316.25 | S31: 78.11 | T31: 82.26 | U31: 12.28 | V31: 13.53 | W31: 75.09 | X31: =ATAN(Y31) -> 1.5531366 | Y31: 56.62 | Z31: 64 | AA31: 52.33
C32: 0374E4 | D32: 84618 | E32: 361.18 | F32: 980.79 | G32: 625.19 | H32: 1084.48 | I32: 730.79 | J32: 1462.21 | K32: -172.64 | L32: -403.85 | M32: 649.97 | N32: 1135.21 | O32: 177.17 | P32: 249.06 | Q32: 752.33 | R32: 1500.22 | S32: 76.29 | T32: 80.69 | U32: 15.78 | V32: 17.8 | W32: 72.25 | X32: =ATAN(Y32) -> 1.5552431 | Y32: 64.29 | Z32: 55 | AA32: 43.33
C33: 0533E2 | D33: 84618 | E33: 369.22 | F33: 981.63 | G33: 605.2 | H33: 1047.71 | I33: 716.63 | J33: 1435.72 | K33: -167.97 | L33: -422.23 | M33: 631.28 | N33: 1096.86 | O33: 164.25 | P33: 280.91 | Q33: 739.2 | R33: 1471.97 | S33: 75.5 | T33: 77.38 | U33: 14.86 | V33: 17.91 | W33: 73.45 | X33: =ATAN(Y33) -> 1.5551872 | Y33: 64.06 | Z33: 50 | AA33: 35.67 | AE33: -
B34: 10 | C34: 0244E3 | D34: =D7*10 -> 94020 | E34: 376.56 | F34: 978.4 | G34: 552.85 | H34: 1008.68 | I34: 674.85 | J34: 1405.24 | K34: -163.81 | L34: -398.04 | M34: 578.68 | N34: 1055.51 | O34: 129.71 | P34: 209.11 | Q34: 696.57 | R34: 1439.22 | S34: 77.47 | T34: 81.4 | U34: 10.44 | V34: 11.56 | W34: 77.2 | X34: =ATAN(Y34) -> 1.5527412 | Y34: 55.38 | Z34: 86 | AA34: 62.33
C35: 0374E4 | D35: 94020 | E35: 363.48 | F35: 963.14 | G35: 654.03 | H35: 1115.57 | I35: 756.85 | J35: 1473.81 | K35: -186.48 | L35: -408.6 | M35: 681.5 | N35: 1171.61 | O35: 186.36 | P35: 257.36 | Q35: 780.96 | R35: 1516.67 | S35: 74.64 | T35: 77.84 | U35: 13.63 | V35: 15.15 | W35: 74.65 | X35: =ATAN(Y35) -> 1.5551408 | Y35: 63.87 | Z35: 73 | AA35: 58.67
C36: 0533E2 | D36: 94020 | E36: 360.76 | F36: 1025.37 | G36: 594.43 | H36: 1060.53 | I36: 703.22 | J36: 1458.71 | K36: -169.96 | L36: -408.18 | M36: 622.15 | N36: 1113.92 | O36: 158.65 | P36: 294.6 | Q36: 727.08 | R36: 1509.42 | S36: 76.39 | T36: 78.1 | U36: 13.61 | V36: 18.03 | W36: 73.45 | X36: =ATAN(Y36) -> 1.5547463 | Y36: 62.3 | Z36: 47 | AA36: 37 | AE36: -
B37: 11 | C37: 0244E3 | D37: =D7*11 -> 103422 | E37: 213.54 | F37: 919.12 | G37: 524.1 | H37: 1188.5 | I37: 584.47 | J37: 1449.28 | K37: -230.52 | L37: -409.55 | M37: 577.46 | N37: 1336.6 | O37: 122.03 | P37: 235.18 | Q37: 634.71 | R37: 1525.28 | S37: 78.96 | T37: 82.03 | U37: 15.82 | V37: 18.64 | W37: 71.62 | X37: =ATAN(Y37) -> 1.554134 | Y37: 60.01 | Z37: 99 | AA37: 74.67
C38: 0374E4 | D38: 103422 | E38: 351.99 | F38: 978.51 | G38: 632.05 | H38: 1141.51 | I38: 732.3 | J38: 1503.5 | K38: -170.6 | L38: -415.93 | M38: 656.23 | N38: 1194.1 | O38: 186.23 | P38: 277.47 | Q38: 753.41 | R38: 1543.81 | S38: 73.81 | T38: 78.37 | U38: 13.33 | V38: 14.7 | W38: 75.15 | X38: =ATAN(Y38) -> 1.5553392 | Y38: 64.69 | Z38: 79 | AA38: 59.67
C39: 0533E2 | D39: 103422 | E39: 356.03 | F39: 981.54 | G39: 579.24 | H39: 1032.01 | I39: 688.41 | J39: 1424.24 | K39: -155.84 | L39: -386.53 | M39: 603.94 | N39: 1085.22 | O39: 159.56 | P39: 271.25 | Q39: 709.51 | R39: 1463.25 | S39: 76.49 | T39: 80.79 | U39: 11.74 | V39: 13.56 | W39: 76.01 | X39: =ATAN(Y39) -> 1.5536659 | Y39: 58.37 | Z39: 49 | AA39: 41 | AE39: -
B40: 12 | C40: 0244E3 | D40: =D7*12 -> 112824 | E40: 366.85 | F40: 950.86 | G40: 613.8 | H40: 1115.08 | I40: 724.1 | J40: 1434.12 | K40: -206.72 | L40: -489.04 | M40: 649.65 | N40: 1198.28 | O40: 145.02 | P40: 215.98 | Q40: 755.21 | R40: 1499.73 | S40: 79.43 | T40: 83.37 | U40: 16.55 | V40: 17.59 | W40: 70.7 | X40: =ATAN(Y40) -> 1.5542168 | Y40: 60.31 | Z40: 104 | AA40: 83.33
C41: 0374E4 | D41: 112824 | E41: 376.23 | F41: 937.71 | G41: 656.68 | H41: 1106.71 | I41: 766.59 | J41: 1450.56 | K41: -156.62 | L41: -361.6 | M41: 676.29 | N41: 1145.55 | O41: 203.59 | P41: 279.74 | Q41: 783.62 | R41: 1480.4 | S41: 74.35 | T41: 77.55 | U41: 10.06 | V41: 11.6 | W41: 78.31 | X41: =ATAN(Y41) -> 1.5540109 | Y41: 59.57 | Z41: 102 | AA41: 69.33
C42: 0533E2 | D42: 112824 | E42: 357.38 | F42: 1020.92 | G42: 595.78 | H42: 1083.39 | I42: 704.06 | J42: 1473.38 | K42: -167.53 | L42: -448.92 | M42: 623.21 | N42: 1146.57 | O42: 162.33 | P42: 321.03 | Q42: 727.74 | R42: 1524.81 | S42: 77.95 | T42: 81.45 | U42: 14.02 | V42: 20.21 | W42: 73.7 | X42: =ATAN(Y42) -> 1.5539572 | Y42: 59.38 | Z42: 51 | AA42: 40 | AE42: -
B43: 13 | C43: 0244E3 | D43: =D7*13 -> 122226 | E43: 379.18 | F43: 972.42 | G43: 608.73 | H43: 1020 | I43: 725.15 | J43: 1399.53 | K43: -180.19 | L43: -420.95 | M43: 637.09 | N43: 1064.88 | O43: 155.06 | P43: 230.96 | Q43: 749.66 | R43: 1440.71 | S43: 76.98 | T43: 79.93 | U43: 12.62 | V43: 21.86 | W43: 75.31 | X43: =ATAN(Y43) -> 1.5539146 | Y43: 59.23 | Z43: 114 | AA43: 106
C44: 0374E4 | D44: 122226 | E44: 359.64 | F44: 977.09 | G44: 748.58 | H44: 1288.28 | I44: 845.07 | J44: 1616.91 | K44: -222.12 | L44: -502.14 | M44: 784.66 | N44: 1368.26 | O44: 227.47 | P44: 319.99 | Q44: 876.08 | R44: 1681.32 | S44: 74.94 | T44: 80.08 | U44: 15.39 | V44: 16.98 | W44: 72.93 | X44: =ATAN(Y44) -> 1.5556161 | Y44: 65.87 | Z44: 110 | AA44: 79
...

Sheet reduite
B1: Trial | C1: Edge | D1: NC | E1: N av | F1: N max | G1: Fpav | H1: Fpmax | I1: Fs av | J1: Fs max | K1: Fpnav | L1: Fpn max | M1: P av | N1: P max | O1: Fz av | P1: Fz max | Q1: R av | R1: R max | S1: AEA av | T1: AEA max | U1: λ av | V1: λ max | W1: η | X1: μe | Y1: β | Z1: VB max | AA1: VB av | AC1: RC
B2: N° | C2: ref | D2: rev
A3: Reduced Values | B3: 1 | C3: 0244E3 | D3: 9402 | E3: =(résultats!E7-résultats!E59)/résultats!E60 -> 0.52862017 | F3: =(résultats!F7-résultats!F59)/résultats!F60 -> 0.13762536 | G3: =(résultats!G7-résultats!G59)/résultats!G60 -> -0.72963189 | H3: =(résultats!H7-résultats!H59)/résultats!H60 -> -0.23367479 | I3: =(résultats!I7-résultats!I59)/résultats!I60 -> -0.60661025 | J3: =(résultats!J7-résultats!J59)/résultats!J60 -> -0.20547401 | K3: =(résultats!K7-résultats!K59)/résultats!K60 -> 0.19495982 | L3: =(résultats!L7-résultats!L59)/résultats!L60 -> -1.1987442 | ... AA3: =(résultats!AA7-résultats!AA59)/résultats!AA60 -> -1.0596506 | AC3: =0.807*G3-0.727*K3+0.808*Q3 -> -1.1964115
C4: 0374E4 | D4: 9402 | E4: =(résultats!E8-résultats!E59)/résultats!E60 -> -0.13486703 | F4: =(résultats!F8-résultats!F59)/résultats!F60 -> -0.65367513 | G4: =(résultats!G8-résultats!G59)/résultats!G60 -> -0.68051066 | H4: =(résultats!H8-résultats!H59)/résultats!H60 -> -0.76847802 | I4: =(résultats!I8-résultats!I59)/résultats!I60 -> -0.69761128 | J4: =(résultats!J8-résultats!J59)/résultats!J60 -> -0.80980835 | K4: =(résultats!K8-résultats!K59)/résultats!K60 -> 0.42955609 | L4: =(résultats!L8-résultats!L59)/résultats!L60 -> 0.55375894 | ... AA4: =(résultats!AA8-résultats!AA59)/résultats!AA60 -> -1.0855018 | AC4: =0.807*G4-0.727*K4+0.808*Q4 -> -1.4347715
C5: 0533E2 | D5: 9402 | E5: =(résultats!E9-résultats!E59)/résultats!E60 -> 0.11845858 | F5: =(résultats!F9-résultats!F59)/résultats!F60 -> -0.95054144 | G5: =(résultats!G9-résultats!G59)/résultats!G60 -> -0.64720813 | H5: =(résultats!H9-résultats!H59)/résultats!H60 -> -0.8076455 | I5: =(résultats!I9-résultats!I59)/résultats!I60 -> -0.61573535 | J5: =(résultats!J9-résultats!J59)/résultats!J60 -> -0.89819828 | K5: =(résultats!K9-résultats!K59)/résultats!K60 -> 0.3897019 | L5: =(résultats!L9-résultats!L59)/résultats!L60 -> 1.4582023 | ... AA5: =(résultats!AA9-résultats!AA59)/résultats!AA60 -> -1.0767123 | AC5: =0.807*G5-0.727*K5+0.808*Q5 -> -1.311209
B6: 2 | C6: 0244E3 | D6: =D3*2 -> 18804 | E6: =(résultats!E10-résultats!E59)/résultats!E60 -> -0.37657516 | F6: =(résultats!F10-résultats!F59)/résultats!F60 -> 0.2317788 | G6: =(résultats!G10-résultats!G59)/résultats!G60 -> -1.4220866 | H6: =(résultats!H10-résultats!H59)/résultats!H60 -> -0.2778132 | I6: =(résultats!I10-résultats!I59)/résultats!I60 -> -1.4101194 | J6: =(résultats!J10-résultats!J59)/résultats!J60 -> -0.28991404 | K6: =(résultats!K10-résultats!K59)/résultats!K60 -> 1.1324391 | L6: =(résultats!L10-résultats!L59)/résultats!L60 -> -0.55253356 | ... AA6: =(résultats!AA10-résultats!AA59)/résultats!AA60 -> -0.99915875 | AC6: =0.807*G6-0.727*K6+0.808*Q6 -> -3.122824
C7: 0374E4 | D7: 18804 | E7: =(résultats!E11-résultats!E59)/résultats!E60 -> 1.6548703 | F7: =(résultats!F11-résultats!F59)/résultats!F60 -> -0.36023882 | G7: =(résultats!G11-résultats!G59)/résultats!G60 -> -0.12031454 | H7: =(résultats!H11-résultats!H59)/résultats!H60 -> -0.41365665 | I7: =(résultats!I11-résultats!I59)/résultats!I60 -> 0.15989845 | J7: =(résultats!J11-résultats!J59)/résultats!J60 -> -0.45466866 | K7: =(résultats!K11-résultats!K59)/résultats!K60 -> -0.033296019 | L7: =(résultats!L11-résultats!L59)/résultats!L60 -> 0.52441431 | ... AA7: =(résultats!AA11-résultats!AA59)/résultats!AA60 -> -0.76649797 | AC7: =0.807*G7-0.727*K7+0.808*Q7 -> 0.057796302
C8: 0533E2 | D8: 18804 | E8: =(résultats!E12-résultats!E59)/résultats!E60 -> 0.85358691 | F8: =(résultats!F12-résultats!F59)/résultats!F60 -> -2.7634668 | G8: =(résultats!G12-résultats!G59)/résultats!G60 -> -0.50103381 | H8: =(résultats!H12-résultats!H59)/résultats!H60 -> -1.4526662 | I8: =(résultats!I12-résultats!I59)/résultats!I60 -> -0.33723219 | J8: =(résultats!J12-résultats!J59)/résultats!J60 -> -2.0396309 | K8: =(résultats!K12-résultats!K59)/résultats!K60 -> 1.3221994 | L8: =(résultats!L12-résultats!L59)/résultats!L60 -> 2.5338925 | ... AA8: =(résultats!AA12-résultats!AA59)/résultats!AA60 -> -1.0681814 | AC8: =0.807*G8-0.727*K8+0.808*Q8 -> -1.7048283
B9: 3 | C9: 0244E3 | D9: =D3*3 -> 28206 | E9: =(résultats!E13-résultats!E59)/résultats!E60 -> 0.3182147 | F9: =(résultats!F13-résultats!F59)/résultats!F60 -> -0.99941891 | G9: =(résultats!G13-résultats!G59)/résultats!G60 -> -1.1015498 | H9: =(résultats!H13-résultats!H59)/résultats!H60 -> -1.23026 | I9: =(résultats!I13-résultats!I59)/résultats!I60 -> -0.96973936 | J9: =(résultats!J13-résultats!J59)/résultats!J60 -> -1.2283219 | K9: =(résultats!K13-résultats!K59)/résultats!K60 -> 0.78824383 | L9: =(résultats!L13-résultats!L59)/résultats!L60 -> 0.82247189 | ... AA9: =(résultats!AA13-résultats!AA59)/résultats!AA60 -> -0.93892546 | AC9: =0.807*G9-0.727*K9+0.808*Q9 -> -2.2631898
C10: 0374E4 | D10: 28206 | E10: =(résultats!E14-résultats!E59)/résultats!E60 -> 0.40211872 | F10: =(résultats!F14-résultats!F59)/résultats!F60 -> -0.14089046 | G10: =(résultats!G14-résultats!G59)/résultats!G60 -> -0.33987336 | H10: =(résultats!H14-résultats!H59)/résultats!H60 -> -0.37166088 | I10: =(résultats!I14-résultats!I59)/résultats!I60 -> -0.28248157 | J10: =(résultats!J14-résultats!J59)/résultats!J60 -> -0.33766392 | K10: =(résultats!K14-résultats!K59)/résultats!K60 -> 0.34169571 | L10: =(résultats!L14-résultats!L59)/résultats!L60 -> 0.20392904 | ... AA10: =(résultats!AA14-résultats!AA59)/résultats!AA60 -> -0.85284097 | AC10: =0.807*G10-0.727*K10+0.808*Q10 -> -0.76655893
C11: 0533E2 | D11: 28206 | E11: =(résultats!E15-résultats!E59)/résultats!E60 -> 0.73095795 | F11: =(résultats!F15-résultats!F59)/résultats!F60 -> -1.5154621 | G11: =(résultats!G15-résultats!G59)/résultats!G60 -> -0.10651777 | H11: =(résultats!H15-résultats!H59)/résultats!H60 -> -0.34774901 | I11: =(résultats!I15-résultats!I59)/résultats!I60 -> -0.0073534488 | J11: =(résultats!J15-résultats!J59)/résultats!J60 -> -0.1517554 | K11: =(résultats!K15-résultats!K59)/résultats!K60 -> -0.21852744 | L11: =(résultats!L15-résultats!L59)/résultats!L60 -> -0.26663303 | ... AA11: =(résultats!AA15-résultats!AA59)/résultats!AA60 -> -0.98209696 | AC11: =0.807*G11-0.727*K11+0.808*Q11 -> 0.075769333
B12: 4 | C12: 0244E3 | D12: =D3*4 -> 37608 | E12: =(résultats!E16-résultats!E59)/résultats!E60 -> 0.20462156 | F12: =(résultats!F16-résultats!F59)/résultats!F60 -> 0.11327238 | G12: =(résultats!G16-résultats!G59)/résultats!G60 -> -1.1096375 | H12: =(résultats!H16-résultats!H59)/résultats!H60 -> -0.73830963 | I12: =(résultats!I16-résultats!I59)/résultats!I60 -> -1.0043648 | J12: =(résultats!J16-résultats!J59)/résultats!J60 -> -0.46967827 | K12: =(résultats!K16-résultats!K59)/résultats!K60 -> 0.75880607 | L12: =(résultats!L16-résultats!L59)/résultats!L60 -> 0.51959341 | ... AA12: =(résultats!AA16-résultats!AA59)/résultats!AA60 -> -0.88722306 | AC12: =0.807*G12-0.727*K12+0.808*Q12 -> -2.2709203
C13: 0374E4 | D13: 37608 | E13: =(résultats!E17-résultats!E59)/résultats!E60 -> 0.1939722 | F13: =(résultats!F17-résultats!F59)/résultats!F60 -> -0.037990524 | G13: =(résultats!G17-résultats!G59)/résultats!G60 -> -0.24234452 | H13: =(résultats!H17-résultats!H59)/résultats!H60 -> -0.26889981 | I13: =(résultats!I17-résultats!I59)/résultats!I60 -> -0.23898108 | J13: =(résultats!J17-résultats!J59)/résultats!J60 -> -0.21390046 | K13: =(résultats!K17-résultats!K59)/résultats!K60 -> 0.24206023 | L13: =(résultats!L17-résultats!L59)/résultats!L60 -> -0.31002116 | ... AA13: =(résultats!AA17-résultats!AA59)/résultats!AA60 -> -0.65456228 | AC13: =0.807*G13-0.727*K13+0.808*Q13 -> -0.57406029
C14: 0533E2 | D14: 37608 | E14: =(résultats!E18-résultats!E59)/résultats!E60 -> 0.7948541 | F14: =(résultats!F18-résultats!F59)/résultats!F60 -> 0.42608818 | G14: =(résultats!G18-résultats!G59)/résultats!G60 -> -0.1119889 | H14: =(résultats!H18-résultats!H59)/résultats!H60 -> 0.22339341 | I14: =(résultats!I18-résultats!I59)/résultats!I60 -> -0.0066034403 | J14: =(résultats!J18-résultats!J59)/résultats!J60 -> 0.31626358 | K14: =(résultats!K18-résultats!K59)/résultats!K60 -> -0.16735103 | L14: =(résultats!L18-résultats!L59)/résultats!L60 -> 0.025555624 | ... AA14: =(résultats!AA18-résultats!AA59)/résultats!AA60 -> -0.86137186 | AC14: =0.807*G14-0.727*K14+0.808*Q14 -> 0.033946148
B15: 5 | C15: 0244E3 | D15: =D3*5 -> 47010 | E15: =(résultats!E19-résultats!E59)/résultats!E60 -> -0.12454038 | F15: =(résultats!F19-résultats!F59)/résultats!F60 -> -1.4895656 | G15: =(résultats!G19-résultats!G59)/résultats!G60 -> -1.1938454 | H15: =(résultats!H19-résultats!H59)/résultats!H60 -> -1.735152 | I15: =(résultats!I19-résultats!I59)/résultats!I60 -> -1.1601165 | J15: =(résultats!J19-résultats!J59)/résultats!J60 -> -1.5850416 | K15: =(résultats!K19-résultats!K59)/résultats!K60 -> 0.91188241 | L15: =(résultats!L19-résultats!L59)/résultats!L60 -> 1.3007893 | ... AA15: =(résultats!AA19-résultats!AA59)/résultats!AA60 -> -0.80113857 | AC15: =0.807*G15-0.727*K15+0.808*Q15 -> -2.5879207
C16: 0374E4 | D16: 47010 | E16: =(résultats!E20-résultats!E59)/résultats!E60 -> -0.129381 | F16: =(résultats!F20-résultats!F59)/résultats!F60 -> -0.57735768 | G16: =(résultats!G20-résultats!G59)/résultats!G60 -> -0.44037563 | H16: =(résultats!H20-résultats!H59)/résultats!H60 -> -0.22681834 | I16: =(résultats!I20-résultats!I59)/résultats!I60 -> -0.48885891 | J16: =(résultats!J20-résultats!J59)/résultats!J60 -> -0.3875204 | K16: =(résultats!K20-résultats!K59)/résultats!K60 -> 0.67728613 | L16: =(résultats!L20-résultats!L59)/résultats!L60 -> 0.14880306 | ... AA16: =(résultats!AA20-résultats!AA59)/résultats!AA60 -> -0.59432899 | AC16: =0.807*G16-0.727*K16+0.808*Q16 -> -1.2691327
C17: 0533E2 | D17: 47010 | E17: =(résultats!E21-résultats!E59)/résultats!E60 -> 1.6471254 | F17: =(résultats!F21-résultats!F59)/résultats!F60 -> 0.47616615 | G17: =(résultats!G21-résultats!G59)/résultats!G60 -> 0.29858371 | H17: =(résultats!H21-résultats!H59)/résultats!H60 -> -0.088403725 | I17: =(résultats!I21-résultats!I59)/résultats!I60 -> 0.52952764 | J17: =(résultats!J21-résultats!J59)/résultats!J60 -> 0.022127867 | K17: =(résultats!K21-résultats!K59)/résultats!K60 -> -0.71761063 | L17: =(résultats!L21-résultats!L59)/résultats!L60 -> -0.2230353 | ... AA17: =(résultats!AA21-résultats!AA59)/résultats!AA60 -> -0.79234917 | AC17: =0.807*G17-0.727*K17+0.808*Q17 -> 1.2237
B18: 6 | C18: 0244E3 | D18: =D3*6 -> 56412 | E18: =(résultats!E22-résultats!E59)/résultats!E60 -> -0.26136848 | F18: =(résultats!F22-résultats!F59)/résultats!F60 -> -0.77869855 | G18: =(résultats!G22-résultats!G59)/résultats!G60 -> -1.2416583 | H18: =(résultats!H22-résultats!H59)/résultats!H60 -> -1.5063179 | I18: =(résultats!I22-résultats!I59)/résultats!I60 -> -1.2307423 | J18: =(résultats!J22-résultats!J59)/résultats!J60 -> -1.3476088 | K18: =(résultats!K22-résultats!K59)/résultats!K60 -> 0.95083082 | L18: =(résultats!L22-résultats!L59)/résultats!L60 -> 1.0314476 | ... AA18: =(résultats!AA22-résultats!AA59)/résultats!AA60 -> -0.66309317 | AC18: =0.807*G18-0.727*K18+0.808*Q18 -> -2.7071268
C19: 0374E4 | D19: 56412 | E19: =(résultats!E23-résultats!E59)/résultats!E60 -> 0.19881282 | F19: =(résultats!F23-résultats!F59)/résultats!F60 -> -2.9359957 | G19: =(résultats!G23-résultats!G59)/résultats!G60 -> -0.61664116 | H19: =(résultats!H23-résultats!H59)/résultats!H60 -> -1.6183352 | I19: =(résultats!I23-résultats!I59)/résultats!I60 -> -0.57048484 | J19: =(résultats!J23-résultats!J59)/résultats!J60 -> -2.1970124 | K19: =(résultats!K23-résultats!K59)/résultats!K60 -> 1.5599659 | L19: =(résultats!L23-résultats!L59)/résultats!L60 -> 2.5722502 | ... AA19: =(résultats!AA23-résultats!AA59)/résultats!AA60 -> -0.51677539 | AC19: =0.807*G19-0.727*K19+0.808*Q19 -> -2.16672
C20: 0533E2 | D20: 56412 | E20: =(résultats!E24-résultats!E59)/résultats!E60 -> 0.2230159 | F20: =(résultats!F24-résultats!F59)/résultats!F60 -> 0.81041943 | G20: =(résultats!G24-résultats!G59)/résultats!G60 -> -0.03622565 | H20: =(résultats!H24-résultats!H59)/résultats!H60 -> 0.077265287 | I20: =(résultats!I24-résultats!I59)/résultats!I60 -> -0.019478586 | J20: =(résultats!J24-résultats!J59)/résultats!J60 -> 0.37946194 | K20: =(résultats!K24-résultats!K59)/résultats!K60 -> -0.62250404 | L20: =(résultats!L24-résultats!L59)/résultats!L60 -> -2.02773 | ... AA20: =(résultats!AA24-résultats!AA59)/résultats!AA60 -> -1.0164791 | AC20: =0.807*G20-0.727*K20+0.808*Q20 -> 0.47717383
B21: 7 | C21: 0244E3 | D21: =D3*7 -> 65814 | E21: =(résultats!E25-résultats!E59)/résultats!E60 -> -0.21425314 | F21: =(résultats!F25-résultats!F59)/résultats!F60 -> -1.4364006 | G21: =(résultats!G25-résultats!G59)/résultats!G60 -> -1.236425 | H21: =(résultats!H25-résultats!H59)/résultats!H60 -> -1.6125072 | I21: =(résultats!I25-résultats!I59)/résultats!I60 -> -1.205742 | J21: =(résultats!J25-résultats!J59)/résultats!J60 -> -1.6637762 | K21: =(résultats!K25-résultats!K59)/résultats!K60 -> 0.97256948 | L21: =(résultats!L25-résultats!L59)/résultats!L60 -> 1.565939 | ... AA21: =(résultats!AA25-résultats!AA59)/résultats!AA60 -> -0.37873 | AC21: =0.807*G21-0.727*K21+0.808*Q21 -> -2.7036038
C22: 0374E4 | D22: 65814 | E22: =(résultats!E25-résultats!E59)/résultats!E60 -> -0.21425314 | F22: =(résultats!F25-résultats!F59)/résultats!F60 -> -1.4364006 | G22: =(résultats!G25-résultats!G59)/résultats!G60 -> -1.236425 | H22: =(résultats!H25-résultats!H59)/résultats!H60 -> -1.6125072 | I22: =(résultats!I25-résultats!I59)/résultats!I60 -> -1.205742 | J22: =(résultats!J25-résultats!J59)/résultats!J60 -> -1.6637762 | K22: =(résultats!K25-résultats!K59)/résultats!K60 -> 0.97256948 | L22: =(résultats!L25-résultats!L59)/résultats!L60 -> 1.565939 | ... AA22: =(résultats!AA25-résultats!AA59)/résultats!AA60 -> -0.37873 | AC22: =0.807*G22-0.727*K22+0.808*Q22 -> -2.7036038
C23: 0533E2 | D23: 65814 | E23: =(résultats!E27-résultats!E59)/résultats!E60 -> -0.66539863 | F23: =(résultats!F27-résultats!F59)/résultats!F60 -> 0.37206571 | G23: =(résultats!G27-résultats!G59)/résultats!G60 -> -0.98986737 | H23: =(résultats!H27-résultats!H59)/résultats!H60 -> -0.29983955 | I23: =(résultats!I27-résultats!I59)/résultats!I60 -> -1.0724905 | J23: =(résultats!J27-résultats!J59)/résultats!J60 -> -0.1639562 | K23: =(résultats!K27-résultats!K59)/résultats!K60 -> 1.4838807 | L23: =(résultats!L27-résultats!L59)/résultats!L60 -> -0.33328726 | ... AA23: =(résultats!AA27-résultats!AA59)/résultats!AA60 -> -0.83552067 | AC23: =0.807*G23-0.727*K23+0.808*Q23 -> -2.774785
B24: 8 | C24: 0244E3 | D24: =D3*8 -> 75216 | E24: =(résultats!E28-résultats!E59)/résultats!E60 -> -0.44757087 | F24: =(résultats!F28-résultats!F59)/résultats!F60 -> -1.7840309 | G24: =(résultats!G28-résultats!G59)/résultats!G60 -> -1.1982461 | H24: =(résultats!H28-résultats!H59)/résultats!H60 -> -1.6158497 | I24: =(résultats!I28-résultats!I59)/résultats!I60 -> -1.2359924 | J24: =(résultats!J28-résultats!J59)/résultats!J60 -> -1.7914018 | K24: =(résultats!K28-résultats!K59)/résultats!K60 -> 1.0074419 | L24: =(résultats!L28-résultats!L59)/résultats!L60 -> 1.735509 | ... AA24: =(résultats!AA28-résultats!AA59)/résultats!AA60 -> -0.24094311 | AC24: =0.807*G24-0.727*K24+0.808*Q24 -> -2.725008
C25: 0374E4 | D25: 75216 | E25: =(résultats!E29-résultats!E59)/résultats!E60 -> -0.02127389 | F25: =(résultats!F29-résultats!F59)/résultats!F60 -> 0.2449843 | G25: =(résultats!G29-résultats!G59)/résultats!G60 -> -0.085227943 | H25: =(résultats!H29-résultats!H59)/résultats!H60 -> -0.0061263055 | I25: =(résultats!I29-résultats!I59)/résultats!I60 -> -0.1174797 | J25: =(résultats!J29-résultats!J59)/résultats!J60 -> 0.11990978 | K25: =(résultats!K29-résultats!K59)/résultats!K60 -> 0.32176861 | L25: =(résultats!L29-résultats!L59)/résultats!L60 -> -0.33412568 | ... AA25: =(résultats!AA29-résultats!AA59)/résultats!AA60 -> -0.3443479 | AC25: =0.807*G25-0.727*K25+0.808*Q25 -> -0.41418735
C26: 0533E2 | D26: 75216 | E26: =(résultats!E30-résultats!E59)/résultats!E60 -> 0.5047398 | F26: =(résultats!F30-résultats!F59)/résultats!F60 -> 0.001454451 | G26: =(résultats!G30-résultats!G59)/résultats!G60 -> -0.24056046 | H26: =(résultats!H30-résultats!H59)/résultats!H60 -> -0.5890961 | I26: =(résultats!I30-résultats!I59)/résultats!I60 -> -0.15948017 | J26: =(résultats!J30-résultats!J59)/résultats!J60 -> -0.4004234 | K26: =(résultats!K30-résultats!K59)/résultats!K60 -> -0.10892841 | L26: =(résultats!L30-résultats!L59)/résultats!L60 -> 0.86544081 | ... AA26: =(résultats!AA30-résultats!AA59)/résultats!AA60 -> -0.76649797 | AC26: =0.807*G26-0.727*K26+0.808*Q26 -> -0.23149232
B27: 9 | C27: 0244E3 | D27: =D3*9 -> 84618 | E27: =(résultats!E31-résultats!E59)/résultats!E60 -> 0.37017065 | F27: =(résultats!F31-résultats!F59)/résultats!F60 -> -1.1964723 | G27: =(résultats!G31-résultats!G59)/résultats!G60 -> -0.85582469 | H27: =(résultats!H31-résultats!H59)/résultats!H60 -> -1.1937494 | I27: =(résultats!I31-résultats!I59)/résultats!I60 -> -0.7346117 | J27: =(résultats!J31-résultats!J59)/résultats!J60 -> -1.271683 | K27: =(résultats!K31-résultats!K59)/résultats!K60 -> 0.52647424 | L27: =(résultats!L31-résultats!L59)/résultats!L60 -> 0.49066799 | ... AA27: =(résultats!AA31-résultats!AA59)/résultats!AA60 -> -0.077305025 | AC27: =0.807*G27-0.727*K27+0.808*Q27 -> -1.6794511
C28: 0374E4 | D28: 84618 | E28: =(résultats!E32-résultats!E59)/résultats!E60 -> -0.18165966 | F28: =(résultats!F32-résultats!F59)/résultats!F60 -> 0.24721379 | G28: =(résultats!G32-résultats!G59)/résultats!G60 -> 0.078668077 | H28: =(résultats!H32-résultats!H59)/résultats!H60 -> 0.12414628 | I28: =(résultats!I32-résultats!I59)/résultats!I60 -> -0.00022836797 | J28: =(résultats!J32-résultats!J59)/résultats!J60 -> 0.21935942 | K28: =(résultats!K32-résultats!K59)/résultats!K60 -> 0.24070156 | L28: =(résultats!L32-résultats!L59)/résultats!L60 -> -0.024959058 | ... AA28: =(résultats!AA32-résultats!AA59)/résultats!AA60 -> -0.30996581 | AC28: =0.807*G28-0.727*K28+0.808*Q28 -> -0.12506668
C29: 0533E2 | D29: 84618 | E29: =(résultats!E33-résultats!E59)/résultats!E60 -> 0.0777974 | F29: =(résultats!F33-résultats!F59)/résultats!F60 -> 0.26161978 | G29: =(résultats!G33-résultats!G59)/résultats!G60 -> -0.1590882 | H29: =(résultats!H33-résultats!H59)/résultats!H60 -> -0.19099338 | I29: =(résultats!I33-résultats!I59)/résultats!I60 -> -0.17723038 | J29: =(résultats!J33-résultats!J59)/résultats!J60 -> -0.013157885 | K29: =(résultats!K33-résultats!K59)/résultats!K60 -> 0.45220052 | L29: =(résultats!L33-résultats!L59)/résultats!L60 -> -0.41021211 | ... AA29: =(résultats!AA33-résultats!AA59)/résultats!AA60 -> -0.50798599 | AC29: =0.807*G29-0.727*K29+0.808*Q29 -> -0.60379103
B30: 10 | C30: 0244E3 | D30: =D3*10 -> 94020 | E30: =(résultats!E34-résultats!E59)/résultats!E60 -> 0.31466491 | F30: =(résultats!F34-résultats!F59)/résultats!F60 -> 0.20622532 | G30: =(résultats!G34-résultats!G59)/résultats!G60 -> -0.78172656 | H30: =(résultats!H34-résultats!H59)/résultats!H60 -> -0.52550252 | I30: =(résultats!I34-résultats!I59)/résultats!I60 -> -0.6994863 | J30: =(résultats!J34-résultats!J59)/résultats!J60 -> -0.28069762 | K30: =(résultats!K34-résultats!K59)/résultats!K60 -> 0.64060216 | L30: =(résultats!L34-résultats!L59)/résultats!L60 -> 0.096821151 | ... AA30: =(résultats!AA34-résultats!AA59)/résultats!AA60 -> 0.18120696 | AC30: =0.807*G30-0.727*K30+0.808*Q30 -> -1.6753571
C31: 0374E4 | D31: 94020 | E31: =(résultats!E35-résultats!E59)/résultats!E60 -> -0.10743687 | F31: =(résultats!F35-résultats!F59)/résultats!F60 -> -0.055483513 | G31: =(résultats!G35-résultats!G59)/résultats!G60 -> 0.42168413 | H31: =(résultats!H35-résultats!H59)/résultats!H60 -> 0.39060513 | I31: =(résultats!I35-résultats!I59)/résultats!I60 -> 0.32552533 | J31: =(résultats!J35-résultats!J59)/résultats!J60 -> 0.321179 | K31: =(résultats!K35-résultats!K59)/résultats!K60 -> -0.38609621 | L31: =(résultats!L35-résultats!L59)/résultats!L60 -> -0.12452119 | ... AA31: =(résultats!AA35-résultats!AA59)/résultats!AA60 -> 0.086591571 | AC31: =0.807*G31-0.727*K31+0.808*Q31 -> 0.89764391
C32: 0533E2 | D32: 94020 | E32: =(résultats!E36-résultats!E59)/100 -> -0.060492308 | F32: =(résultats!F36-résultats!F59)/100 -> 0.58994808 | G32: =(résultats!G36-résultats!G59)/100 -> -0.24145769 | H32: =(résultats!H36-résultats!H59)/100 -> -0.094648077 | I32: =(résultats!I36-résultats!I59)/100 -> -0.27588269 | J32: =(résultats!J36-résultats!J59)/100 -> 0.21490962 | K32: =(résultats!K36-résultats!K59)/100 -> 0.079948077 | L32: =(résultats!L36-résultats!L59)/100 -> -0.055207692 | ... AA32: =(résultats!AA36-résultats!AA59)/100 -> -0.18320385 | AC32: =0.807*G32-0.727*K32+0.808*Q32 -> -0.46780872
B33: 11 | C33: 0244E3 | D33: =D3*11 -> 103422 | E33: =(résultats!E37-résultats!E59)/résultats!E60 -> -4.9461174 | F33: =(résultats!F37-résultats!F59)/résultats!F60 -> -0.81042603 | G33: =(résultats!G37-résultats!G59)/résultats!G60 -> -1.1236722 | H33: =(résultats!H37-résultats!H59)/résultats!H60 -> 1.0156564 | I33: =(résultats!I37-résultats!I59)/résultats!I60 -> -1.8292491 | J33: =(résultats!J37-résultats!J59)/résultats!J60 -> 0.1058657 | K33: =(résultats!K37-résultats!K59)/résultats!K60 -> -2.3806174 | L33: =(résultats!L37-résultats!L59)/résultats!L60 -> -0.14443362 | ... AA33: =(résultats!AA37-résultats!AA59)/résultats!AA60 -> 0.50021074 | AC33: =0.807*G33-0.727*K33+0.808*Q33 -> -0.38193885
C34: 0374E4 | D34: 103422 | E34: =(résultats!E38-résultats!E59)/résultats!E60 -> -0.47822811 | F34: =(résultats!F38-résultats!F59)/résultats!F60 -> 0.20811182 | G34: =(résultats!G38-résultats!G59)/résultats!G60 -> 0.16025927 | H34: =(résultats!H38-résultats!H59)/résultats!H60 -> 0.61292557 | I34: =(résultats!I38-résultats!I59)/résultats!I60 -> 0.018646846 | J34: =(résultats!J38-résultats!J59)/résultats!J60 -> 0.58178447 | K34: =(résultats!K38-résultats!K59)/résultats!K60 -> 0.33309083 | L34: =(résultats!L38-résultats!L59)/résultats!L60 -> -0.27816128 | ... AA34: =(résultats!AA38-résultats!AA59)/résultats!AA60 -> 0.11244277 | AC34: =0.807*G34-0.727*K34+0.808*Q34 -> -0.1154419
C35: 0533E2 | D35: 103422 | E35: =(résultats!E39-résultats!E59)/résultats!E60 -> -0.34785417 | F35: =(résultats!F39-résultats!F59)/résultats!F60 -> 0.26007629 | G35: =(résultats!G39-résultats!G59)/résultats!G60 -> -0.46785022 | H35: =(résultats!H39-résultats!H59)/résultats!H60 -> -0.32555125 | I35: =(résultats!I39-résultats!I59)/résultats!I60 -> -0.52998438 | J35: =(résultats!J39-résultats!J59)/résultats!J60 -> -0.11392416 | K35: =(résultats!K39-résultats!K59)/résultats!K60 -> 1.0015543 | L35: =(résultats!L39-résultats!L59)/résultats!L60 -> 0.33807592 | ... AA35: =(résultats!AA39-résultats!AA59)/résultats!AA60 -> -0.3701991 | AC35: =0.807*G35-0.727*K35+0.808*Q35 -> -1.5533018
B36: 12 | C36: 0244E3 | D36: =D3*12 -> 112824 | E36: =(résultats!E40-résultats!E59)/résultats!E60 -> 0.0013156548 | F36: =(résultats!F40-résultats!F59)/résultats!F60 -> -0.26608538 | G36: =(résultats!G40-résultats!G59)/résultats!G60 -> -0.056801856 | H36: =(résultats!H40-résultats!H59)/résultats!H60 -> 0.38640555 | I36: =(résultats!I40-résultats!I59)/résultats!I60 -> -0.083854317 | J36: =(résultats!J40-résultats!J59)/résultats!J60 -> -0.027201966 | K36: =(résultats!K40-résultats!K59)/résultats!K60 -> -1.3027427 | L36: =(résultats!L40-résultats!L59)/résultats!L60 -> -1.8105797 | ... AA36: =(résultats!AA40-résultats!AA59)/résultats!AA60 -> 0.72408212 | AC36: =0.807*G36-0.727*K36+0.808*Q36 -> 0.91688682
C37: 0374E4 | D37: 112824 | E37: =(résultats!E41-résultats!E59)/résultats!E60 -> 0.30401556 | F37: =(résultats!F41-résultats!F59)/résultats!F60 -> -0.49160773 | G37: =(résultats!G41-résultats!G59)/résultats!G60 -> 0.4532026 | H37: =(résultats!H41-résultats!H59)/résultats!H60 -> 0.31466992 | I37: =(résultats!I41-résultats!I59)/résultats!I60 -> 0.44727671 | J37: =(résultats!J41-résultats!J59)/résultats!J60 -> 0.11710096 | K37: =(résultats!K41-résultats!K59)/résultats!K60 -> 0.96622904 | L37: =(résultats!L41-résultats!L59)/résultats!L60 -> 0.86061991 | ... AA37: =(résultats!AA41-résultats!AA59)/résultats!AA60 -> 0.36216534 | AC37: =0.807*G37-0.727*K37+0.808*Q37 -> -0.033097426
C38: 0533E2 | D38: 112824 | E38: =(résultats!E42-résultats!E59)/résultats!E60 -> -0.30428862 | F38: =(résultats!F42-résultats!F59)/résultats!F60 -> 0.93544285 | G38: =(résultats!G42-résultats!G59)/résultats!G60 -> -0.27112742 | H38: =(résultats!H42-résultats!H59)/résultats!H60 -> 0.11480436 | I38: =(résultats!I42-résultats!I59)/résultats!I60 -> -0.33435716 | J38: =(résultats!J42-résultats!J59)/résultats!J60 -> 0.31740466 | K38: =(résultats!K42-résultats!K59)/résultats!K60 -> 0.47212762 | L38: =(résultats!L42-résultats!L59)/résultats!L60 -> -0.96964649 | ... AA38: =(résultats!AA42-résultats!AA59)/résultats!AA60 -> -0.3960503 | AC38: =0.807*G38-0.727*K38+0.808*Q38 -> -0.82486064
B39: 13 | C39: 0244E3 | D39: =D3*13 -> 122226 | E39: =(résultats!E43-résultats!E59)/résultats!E60 -> 0.39921435 | F39: =(résultats!F43-résultats!F59)/résultats!F60 -> 0.10366839 | G39: =(résultats!G43-résultats!G59)/résultats!G60 -> -0.11710322 | H39: =(résultats!H43-résultats!H59)/résultats!H60 -> -0.42848373 | I39: =(résultats!I43-résultats!I59)/résultats!I60 -> -0.070729168 | J39: =(résultats!J43-résultats!J59)/résultats!J60 -> -0.33081743 | K39: =(résultats!K43-résultats!K59)/résultats!K60 -> -0.1012293 | L39: =(résultats!L43-résultats!L59)/résultats!L60 -> -0.38338273 | ... AA39: =(résultats!AA43-résultats!AA59)/résultats!AA60 -> 1.3101288 | AC39: =0.807*G39-0.727*K39+0.808*Q39 -> -0.061535452
C40: 0374E4 | D40: 122226 | E40: =(résultats!E44-résultats!E59)/résultats!E60 -> -0.23135666 | F40: =(résultats!F44-résultats!F59)/résultats!F60 -> 0.18375883 | G40: =(résultats!G44-résultats!G59)/résultats!G60 -> 1.5462392 | H40: =(résultats!H44-résultats!H59)/résultats!H60 -> 1.8708273 | I40: =(résultats!I44-résultats!I59)/résultats!I60 -> 1.4282878 | J40: =(résultats!J44-résultats!J59)/résultats!J60 -> 1.5772464 | K40: =(résultats!K44-résultats!K59)/résultats!K60 -> -2.000191 | L40: =(résultats!L44-résultats!L59)/résultats!L60 -> -2.0851616 | ... AA40: =(résultats!AA44-résultats!AA59)/résultats!AA60 -> 0.61214643 | AC40: =0.807*G40-0.727*K40+0.808*Q40 -> 3.9428128
...

Sheet corr_matrix
A1: Correlation Matrix
C2: N av | D2: N max | E2: Fpav | F2: Fpmax | G2: Fs av | H2: Fs max | I2: Fpnav | J2: Fpn max | K2: P av | L2: P max | M2: Fz av | N2: Fz max | O2: R av | P2: R max | Q2: AEA av | R2: AEA max | S2: λ av | T2: λ max | U2: η | V2: μe | W2: β | X2: VB max | Y2: VB av | Z2: Rt | AA2: Ra | AB2: Curve
B3: N av | C3: =CORREL(résultats!$E7:$E58,résultats!E7:E58) -> 1 | D3: =CORREL(résultats!$E7:$E58,résultats!F7:F58) -> 0.021600429 | E3: =CORREL(résultats!$E7:$E58,résultats!G7:G58) -> 0.027286331 | F3: =CORREL(résultats!$E7:$E58,résultats!H7:H58) -> -0.32187437 | G3: =CORREL(résultats!$E7:$E58,résultats!I7:I58) -> 0.20630808 | H3: =CORREL(résultats!$E7:$E58,résultats!J7:J58) -> -0.19062492 | I3: =CORREL(résultats!$E7:$E58,résultats!K7:K58) -> 0.19318048 | J3: =CORREL(résultats!$E7:$E58,résultats!L7:L58) -> 0.1541417 | ... Y3: =CORREL(résultats!$E7:$E58,résultats!AA7:AA58) -> -0.26216943
B4: N max | C4: =CORREL(résultats!$F7:$F58,résultats!E7:E58) -> 0.021600429 | D4: =CORREL(résultats!$F7:$F58,résultats!F7:F58) -> 1 | E4: =CORREL(résultats!$F7:$F58,résultats!G7:G58) -> 0.55617731 | F4: =CORREL(résultats!$F7:$F58,résultats!H7:H58) -> 0.70422869 | G4: =CORREL(résultats!$F7:$F58,résultats!I7:I58) -> 0.5485317 | H4: =CORREL(résultats!$F7:$F58,résultats!J7:J58) -> 0.83445079 | I4: =CORREL(résultats!$F7:$F58,résultats!K7:K58) -> -0.44896322 | J4: =CORREL(résultats!$F7:$F58,résultats!L7:L58) -> -0.70714557 | ... Y4: =CORREL(résultats!$F7:$F58,résultats!AA7:AA58) -> 0.40585741
B5: Fpav | C5: =CORREL(résultats!$G7:$G58,résultats!E7:E58) -> 0.027286331 | D5: =CORREL(résultats!$G7:$G58,résultats!F7:F58) -> 0.55617731 | E5: =CORREL(résultats!$G7:$G58,résultats!G7:G58) -> 1 | F5: =CORREL(résultats!$G7:$G58,résultats!H7:H58) -> 0.84767756 | G5: =CORREL(résultats!$G7:$G58,résultats!I7:I58) -> 0.97934692 | H5: =CORREL(résultats!$G7:$G58,résultats!J7:J58) -> 0.8399825 | I5: =CORREL(résultats!$G7:$G58,résultats!K7:K58) -> -0.748292 | J5: =CORREL(résultats!$G7:$G58,résultats!L7:L58) -> -0.552311 | ... Y5: =CORREL(résultats!$G7:$G58,résultats!AA7:AA58) -> 0.71295817
B6: Fpmax | C6: =+CORREL(résultats!$H7:$H58,résultats!E7:E58) -> -0.32187437 | D6: =+CORREL(résultats!$H7:$H58,résultats!F7:F58) -> 0.70422869 | E6: =+CORREL(résultats!$H7:$H58,résultats!G7:G58) -> 0.84767756 | F6: =+CORREL(résultats!$H7:$H58,résultats!H7:H58) -> 1 | G6: =+CORREL(résultats!$H7:$H58,résultats!I7:I58) -> 0.76679669 | H6: =+CORREL(résultats!$H7:$H58,résultats!J7:J58) -> 0.96828356 | I6: =+CORREL(résultats!$H7:$H58,résultats!K7:K58) -> -0.75192197 | J6: =+CORREL(résultats!$H7:$H58,résultats!L7:L58) -> -0.74530799 | ... Y6: =+CORREL(résultats!$H7:$H58,résultats!AA7:AA58) -> 0.66070284
B7: Fs av | C7: =CORREL(résultats!$I7:$I58,résultats!E7:E58) -> 0.20630808 | D7: =CORREL(résultats!$I7:$I58,résultats!F7:F58) -> 0.5485317 | E7: =CORREL(résultats!$I7:$I58,résultats!G7:G58) -> 0.97934692 | F7: =CORREL(résultats!$I7:$I58,résultats!H7:H58) -> 0.76679669 | G7: =CORREL(résultats!$I7:$I58,résultats!I7:I58) -> 1 | H7: =CORREL(résultats!$I7:$I58,résultats!J7:J58) -> 0.78369224 | I7: =CORREL(résultats!$I7:$I58,résultats!K7:K58) -> -0.70332091 | J7: =CORREL(résultats!$I7:$I58,résultats!L7:L58) -> -0.51372405 | ... Y7: =CORREL(résultats!$I7:$I58,résultats!AA7:AA58) -> 0.65422269
B8: Fs max | C8: =CORREL(résultats!$J7:$J58,résultats!E7:E58) -> -0.19062492 | D8: =CORREL(résultats!$J7:$J58,résultats!F7:F58) -> 0.83445079 | E8: =CORREL(résultats!$J7:$J58,résultats!G7:G58) -> 0.8399825 | F8: =CORREL(résultats!$J7:$J58,résultats!H7:H58) -> 0.96828356 | G8: =CORREL(résultats!$J7:$J58,résultats!I7:I58) -> 0.78369224 | H8: =CORREL(résultats!$J7:$J58,résultats!J7:J58) -> 1 | I8: =CORREL(résultats!$J7:$J58,résultats!K7:K58) -> -0.70730124 | J8: =CORREL(résultats!$J7:$J58,résultats!L7:L58) -> -0.78698119 | ... Y8: =CORREL(résultats!$J7:$J58,résultats!AA7:AA58) -> 0.61358036
B9: Fpnav | C9: =CORREL(résultats!$K7:$K58,résultats!E7:E58) -> 0.19318048 | D9: =CORREL(résultats!$K7:$K58,résultats!F7:F58) -> -0.44896322 | E9: =CORREL(résultats!$K7:$K58,résultats!G7:G58) -> -0.748292 | F9: =CORREL(résultats!$K7:$K58,résultats!H7:H58) -> -0.75192197 | G9: =CORREL(résultats!$K7:$K58,résultats!I7:I58) -> -0.70332091 | H9: =CORREL(résultats!$K7:$K58,résultats!J7:J58) -> -0.70730124 | I9: =CORREL(résultats!$K7:$K58,résultats!K7:K58) -> 1 | J9: =CORREL(résultats!$K7:$K58,résultats!L7:L58) -> 0.63643723 | ... Y9: =CORREL(résultats!$K7:$K58,résultats!AA7:AA58) -> -0.60764461
B10: Fpn max | C10: =CORREL(résultats!$L7:$L58,résultats!E7:E58) -> 0.1541417 | D10: =CORREL(résultats!$L7:$L58,résultats!F7:F58) -> -0.70714557 | E10: =CORREL(résultats!$L7:$L58,résultats!G7:G58) -> -0.552311 | F10: =CORREL(résultats!$L7:$L58,résultats!H7:H58) -> -0.74530799 | G10: =CORREL(résultats!$L7:$L58,résultats!I7:I58) -> -0.51372405 | H10: =CORREL(résultats!$L7:$L58,résultats!J7:J58) -> -0.78698119 | I10: =CORREL(résultats!$L7:$L58,résultats!K7:K58) -> 0.63643723 | J10: =CORREL(résultats!$L7:$L58,résultats!L7:L58) -> 1 | ... Y10: =CORREL(résultats!$L7:$L58,résultats!AA7:AA58) -> -0.37741284
B11: P av | C11: =CORREL(résultats!$M7:$M58,résultats!E7:E58) -> 3.2622404e-05 | D11: =CORREL(résultats!$M7:$M58,résultats!F7:F58) -> 0.56291768 | E11: =CORREL(résultats!$M7:$M58,résultats!G7:G58) -> 0.99830016 | F11: =CORREL(résultats!$M7:$M58,résultats!H7:H58) -> 0.86139411 | G11: =CORREL(résultats!$M7:$M58,résultats!I7:I58) -> 0.97385635 | H11: =CORREL(résultats!$M7:$M58,résultats!J7:J58) -> 0.84991542 | I11: =CORREL(résultats!$M7:$M58,résultats!K7:K58) -> -0.78393941 | J11: =CORREL(résultats!$M7:$M58,résultats!L7:L58) -> -0.57515966 | ... Y11: =CORREL(résultats!$M7:$M58,résultats!AA7:AA58) -> 0.71994246
B12: P max | C12: =CORREL(résultats!$N7:$N58,résultats!E7:E58) -> -0.38604284 | D12: =CORREL(résultats!$N7:$N58,résultats!F7:F58) -> 0.67472546 | E12: =CORREL(résultats!$N7:$N58,résultats!G7:G58) -> 0.80891773 | F12: =CORREL(résultats!$N7:$N58,résultats!H7:H58) -> 0.99074417 | G12: =CORREL(résultats!$N7:$N58,résultats!I7:I58) -> 0.71980177 | H12: =CORREL(résultats!$N7:$N58,résultats!J7:J58) -> 0.94937844 | I12: =CORREL(résultats!$N7:$N58,résultats!K7:K58) -> -0.79248556 | J12: =CORREL(résultats!$N7:$N58,résultats!L7:L58) -> -0.76202915 | ... Y12: =CORREL(résultats!$N7:$N58,résultats!AA7:AA58) -> 0.64144129
B13: Fz av | C13: =CORREL(résultats!$O7:$O58,résultats!E7:E58) -> -0.13520276 | D13: =CORREL(résultats!$O7:$O58,résultats!F7:F58) -> 0.52548207 | E13: =CORREL(résultats!$O7:$O58,résultats!G7:G58) -> 0.96652564 | F13: =CORREL(résultats!$O7:$O58,résultats!H7:H58) -> 0.86128032 | G13: =CORREL(résultats!$O7:$O58,résultats!I7:I58) -> 0.91469419 | H13: =CORREL(résultats!$O7:$O58,résultats!J7:J58) -> 0.83593845 | I13: =CORREL(résultats!$O7:$O58,résultats!K7:K58) -> -0.63265321 | J13: =CORREL(résultats!$O7:$O58,résultats!L7:L58) -> -0.50209567 | ... Y13: =CORREL(résultats!$O7:$O58,résultats!AA7:AA58) -> 0.73002953
B14: Fz max | C14: =CORREL(résultats!$P7:$P58,résultats!E7:E58) -> -0.11661024 | D14: =CORREL(résultats!$P7:$P58,résultats!F7:F58) -> 0.73087141 | E14: =CORREL(résultats!$P7:$P58,résultats!G7:G58) -> 0.85457147 | F14: =CORREL(résultats!$P7:$P58,résultats!H7:H58) -> 0.83792437 | G14: =CORREL(résultats!$P7:$P58,résultats!I7:I58) -> 0.80949074 | H14: =CORREL(résultats!$P7:$P58,résultats!J7:J58) -> 0.8637846 | I14: =CORREL(résultats!$P7:$P58,résultats!K7:K58) -> -0.61478771 | J14: =CORREL(résultats!$P7:$P58,résultats!L7:L58) -> -0.61764661 | ... Y14: =CORREL(résultats!$P7:$P58,résultats!AA7:AA58) -> 0.59499337
B15: R av | C15: =CORREL(résultats!$Q7:$Q58,résultats!E7:E58) -> 0.1474922 | D15: =CORREL(résultats!$Q7:$Q58,résultats!F7:F58) -> 0.5516672 | E15: =CORREL(résultats!$Q7:$Q58,résultats!G7:G58) -> 0.99070039 | F15: =CORREL(résultats!$Q7:$Q58,résultats!H7:H58) -> 0.80010853 | G15: =CORREL(résultats!$Q7:$Q58,résultats!I7:I58) -> 0.99363302 | H15: =CORREL(résultats!$Q7:$Q58,résultats!J7:J58) -> 0.80648476 | I15: =CORREL(résultats!$Q7:$Q58,résultats!K7:K58) -> -0.75043017 | J15: =CORREL(résultats!$Q7:$Q58,résultats!L7:L58) -> -0.54136199 | ... Y15: =CORREL(résultats!$Q7:$Q58,résultats!AA7:AA58) -> 0.6756731
B16: R max | C16: =CORREL(résultats!$R7:$R58,résultats!E7:E58) -> -0.21804826 | D16: =CORREL(résultats!$R7:$R58,résultats!F7:F58) -> 0.83489364 | E16: =CORREL(résultats!$R7:$R58,résultats!G7:G58) -> 0.81717904 | F16: =CORREL(résultats!$R7:$R58,résultats!H7:H58) -> 0.96876075 | G16: =CORREL(résultats!$R7:$R58,résultats!I7:I58) -> 0.75631549 | H16: =CORREL(résultats!$R7:$R58,résultats!J7:J58) -> 0.9971768 | I16: =CORREL(résultats!$R7:$R58,résultats!K7:K58) -> -0.72365649 | J16: =CORREL(résultats!$R7:$R58,résultats!L7:L58) -> -0.80876407 | ... Y16: =CORREL(résultats!$R7:$R58,résultats!AA7:AA58) -> 0.6003711
B17: AEA av | C17: =CORREL(résultats!$S7:$S58,résultats!E7:E58) -> 0.039426929 | D17: =CORREL(résultats!$S7:$S58,résultats!F7:F58) -> -0.44471845 | E17: =CORREL(résultats!$S7:$S58,résultats!G7:G58) -> -0.75422118 | F17: =CORREL(résultats!$S7:$S58,résultats!H7:H58) -> -0.65569048 | G17: =CORREL(résultats!$S7:$S58,résultats!I7:I58) -> -0.73082721 | H17: =CORREL(résultats!$S7:$S58,résultats!J7:J58) -> -0.65274641 | I17: =CORREL(résultats!$S7:$S58,résultats!K7:K58) -> 0.33304222 | J17: =CORREL(résultats!$S7:$S58,résultats!L7:L58) -> 0.25089921 | ... Y17: =CORREL(résultats!$S7:$S58,résultats!AA7:AA58) -> -0.54962532
B18: AEA max | C18: =CORREL(résultats!$T7:$T58,résultats!E7:E58) -> -0.026935126 | D18: =CORREL(résultats!$T7:$T58,résultats!F7:F58) -> -0.48294707 | E18: =CORREL(résultats!$T7:$T58,résultats!G7:G58) -> -0.6015752 | F18: =CORREL(résultats!$T7:$T58,résultats!H7:H58) -> -0.51795097 | G18: =CORREL(résultats!$T7:$T58,résultats!I7:I58) -> -0.60006224 | H18: =CORREL(résultats!$T7:$T58,résultats!J7:J58) -> -0.53773677 | I18: =CORREL(résultats!$T7:$T58,résultats!K7:K58) -> 0.27212933 | J18: =CORREL(résultats!$T7:$T58,résultats!L7:L58) -> 0.18687275 | ... Y18: =CORREL(résultats!$T7:$T58,résultats!AA7:AA58) -> -0.42311639
B19: λ av | C19: =CORREL(résultats!$U7:$U58,résultats!E7:E58) -> -0.13641241 | D19: =CORREL(résultats!$U7:$U58,résultats!F7:F58) -> 0.16381678 | E19: =CORREL(résultats!$U7:$U58,résultats!G7:G58) -> 0.10087023 | F19: =CORREL(résultats!$U7:$U58,résultats!H7:H58) -> 0.18516693 | G19: =CORREL(résultats!$U7:$U58,résultats!I7:I58) -> 0.054784366 | H19: =CORREL(résultats!$U7:$U58,résultats!J7:J58) -> 0.19050691 | I19: =CORREL(résultats!$U7:$U58,résultats!K7:K58) -> -0.34932518 | J19: =CORREL(résultats!$U7:$U58,résultats!L7:L58) -> -0.27276268 | ... Y19: =CORREL(résultats!$U7:$U58,résultats!AA7:AA58) -> 0.017122082
B20: λ max | C20: =CORREL(résultats!$V7:$V58,résultats!E7:E58) -> -0.088937667 | D20: =CORREL(résultats!$V7:$V58,résultats!F7:F58) -> 0.15776615 | E20: =CORREL(résultats!$V7:$V58,résultats!G7:G58) -> -0.0024184587 | F20: =CORREL(résultats!$V7:$V58,résultats!H7:H58) -> 0.082734253 | G20: =CORREL(résultats!$V7:$V58,résultats!I7:I58) -> -0.028466218 | H20: =CORREL(résultats!$V7:$V58,résultats!J7:J58) -> 0.10617724 | I20: =CORREL(résultats!$V7:$V58,résultats!K7:K58) -> -0.2409492 | J20: =CORREL(résultats!$V7:$V58,résultats!L7:L58) -> -0.2462418 | ... Y20: =CORREL(résultats!$V7:$V58,résultats!AA7:AA58) -> -0.037040094
B21: η | C21: =CORREL(résultats!$W7:$W58,résultats!E7:E58) -> 0.12154496 | D21: =CORREL(résultats!$W7:$W58,résultats!F7:F58) -> -0.099173716 | E21: =CORREL(résultats!$W7:$W58,résultats!G7:G58) -> 0.041303416 | F21: =CORREL(résultats!$W7:$W58,résultats!H7:H58) -> -0.071427443 | G21: =CORREL(résultats!$W7:$W58,résultats!I7:I58) -> 0.080809026 | H21: =CORREL(résultats!$W7:$W58,résultats!J7:J58) -> -0.079205407 | I21: =CORREL(résultats!$W7:$W58,résultats!K7:K58) -> 0.25913461 | J21: =CORREL(résultats!$W7:$W58,résultats!L7:L58) -> 0.24206509 | ... Y21: =CORREL(résultats!$W7:$W58,résultats!AA7:AA58) -> 0.084867495
B22: μe | C22: =CORREL(résultats!$X7:$X58,résultats!E7:E58) -> -0.10800995 | D22: =CORREL(résultats!$X7:$X58,résultats!F7:F58) -> 0.51053682 | E22: =CORREL(résultats!$X7:$X58,résultats!G7:G58) -> 0.80119019 | F22: =CORREL(résultats!$X7:$X58,résultats!H7:H58) -> 0.73968447 | G22: =CORREL(résultats!$X7:$X58,résultats!I7:I58) -> 0.74706398 | H22: =CORREL(résultats!$X7:$X58,résultats!J7:J58) -> 0.73845191 | I22: =CORREL(résultats!$X7:$X58,résultats!K7:K58) -> -0.63271845 | J22: =CORREL(résultats!$X7:$X58,résultats!L7:L58) -> -0.46396776 | ... Y22: =CORREL(résultats!$X7:$X58,résultats!AA7:AA58) -> 0.49399742
B23: β | C23: =CORREL(résultats!$Y7:$Y58,résultats!E7:E58) -> -0.12923021 | D23: =CORREL(résultats!$Y7:$Y58,résultats!F7:F58) -> 0.51916243 | E23: =CORREL(résultats!$Y7:$Y58,résultats!G7:G58) -> 0.82867526 | F23: =CORREL(résultats!$Y7:$Y58,résultats!H7:H58) -> 0.76592415 | G23: =CORREL(résultats!$Y7:$Y58,résultats!I7:I58) -> 0.77071125 | H23: =CORREL(résultats!$Y7:$Y58,résultats!J7:J58) -> 0.76134859 | I23: =CORREL(résultats!$Y7:$Y58,résultats!K7:K58) -> -0.64714243 | J23: =CORREL(résultats!$Y7:$Y58,résultats!L7:L58) -> -0.47602284 | ... Y23: =CORREL(résultats!$Y7:$Y58,résultats!AA7:AA58) -> 0.52205229
B24: VB max | C24: =CORREL(résultats!$Z7:$Z58,résultats!E7:E58) -> -0.28674502 | D24: =CORREL(résultats!$Z7:$Z58,résultats!F7:F58) -> 0.39289659 | E24: =CORREL(résultats!$Z7:$Z58,résultats!G7:G58) -> 0.74494945 | F24: =CORREL(résultats!$Z7:$Z58,résultats!H7:H58) -> 0.69707107 | G24: =CORREL(résultats!$Z7:$Z58,résultats!I7:I58) -> 0.67968591 | H24: =CORREL(résultats!$Z7:$Z58,résultats!J7:J58) -> 0.63896903 | I24: =CORREL(résultats!$Z7:$Z58,résultats!K7:K58) -> -0.62415597 | J24: =CORREL(résultats!$Z7:$Z58,résultats!L7:L58) -> -0.39193031 | ... Y24: =CORREL(résultats!$Z7:$Z58,résultats!AA7:AA58) -> 0.98940615
B25: VB av | C25: =CORREL(résultats!$AA7:$AA58,résultats!E7:E58) -> -0.26216943 | D25: =CORREL(résultats!$AA7:$AA58,résultats!F7:F58) -> 0.40585741 | E25: =CORREL(résultats!$AA7:$AA58,résultats!G7:G58) -> 0.71295817 | F25: =CORREL(résultats!$AA7:$AA58,résultats!H7:H58) -> 0.66070284 | G25: =CORREL(résultats!$AA7:$AA58,résultats!I7:I58) -> 0.65422269 | H25: =CORREL(résultats!$AA7:$AA58,résultats!J7:J58) -> 0.61358036 | I25: =CORREL(résultats!$AA7:$AA58,résultats!K7:K58) -> -0.60764461 | J25: =CORREL(résultats!$AA7:$AA58,résultats!L7:L58) -> -0.37741284 | ... Y25: =CORREL(résultats!$AA7:$AA58,résultats!AA7:AA58) -> 1
B26: Rt
B27: Ra
B28: Curve

Sheet vbmax
A1: RC:Relevent Criterion Considering VB max
B2: Vb max | C2: RC | D2: f(RC) | G2: Vb max | H2: RC | I2: f(RC) | L2: Vb max | M2: RC | N2: f(RC)
B3: -1.0208452 | C3: -1.1964115 | D3: =0.661*C3 + 0.9972 -> 0.20637199 | G3: -1.0208452 | H3: -1.4347715 | I3: =0.3644*H3 - 0.0953 -> -0.61813075 | L3: -1.039322 | M3: -1.311209 | N3: =0.3461*M3 - 0.285 -> -0.73880944
B4: -0.9838915 | C4: -3.122824 | D4: =0.661*C4 + 0.9972 -> -1.0669867 | G4: -0.7806463 | H4: 0.057796302 | I4: =0.3644*H4 - 0.0953 -> -0.074239028 | L4: -1.0023683 | M4: -1.7048283 | N4: =0.3461*M4 - 0.285 -> -0.87504107
B5: -0.90998415 | C5: -2.2631898 | D5: =0.661*C5 + 0.9972 -> -0.49876849 | G5: -0.79912314 | H5: -0.76655893 | I5: =0.3644*H5 - 0.0953 -> -0.37463407 | L5: -0.94693783 | M5: 0.075769333 | N5: =0.3461*M5 - 0.285 -> -0.25877623
B6: -0.89150732 | C6: -2.2709203 | D6: =0.661*C6 + 0.9972 -> -0.50387834 | G6: -0.61435478 | H6: -0.57406029 | I6: =0.3644*H6 - 0.0953 -> -0.30448757 | L6: -0.83607681 | M6: 0.033946148 | N6: =0.3461*M6 - 0.285 -> -0.27325124
B7: -0.81759998 | C7: -2.5879207 | D7: =0.661*C7 + 0.9972 -> -0.71341561 | G7: -0.55892428 | H7: -1.2691327 | I7: =0.3644*H7 - 0.0953 -> -0.55777195 | L7: -0.76216947 | M7: 1.2237 | N7: =0.3461*M7 - 0.285 -> 0.13852258
B8: -0.66978529 | C8: -2.7071268 | D8: =0.661*C8 + 0.9972 -> -0.79221082 | G8: -0.54044744 | H8: -2.16672 | I8: =0.3644*H8 - 0.0953 -> -0.88485276 | L8: -0.94693783 | M8: 0.47717383 | N8: =0.3461*M8 - 0.285 -> -0.11985014
B9: -0.33720225 | C9: -2.7036038 | D9: =0.661*C9 + 0.9972 -> -0.78988213 | G9: -0.33720225 | H9: -2.7036038 | I9: =0.3644*H9 - 0.0953 -> -1.0804932 | L9: -0.87303048 | M9: -2.774785 | N9: =0.3461*M9 - 0.285 -> -1.2453531
B10: -0.28177174 | C10: -2.725008 | D10: =0.661*C10 + 0.9972 -> -0.80403028 | G10: -0.39263276 | H10: -0.41418735 | I10: =0.3644*H10 - 0.0953 -> -0.24622987 | L10: -0.76216947 | M10: -0.23149232 | N10: =0.3461*M10 - 0.285 -> -0.36511949
B11: -0.13395706 | C11: -1.6794511 | D11: =0.661*C11 + 0.9972 -> -0.11291718 | G11: -0.30024858 | H11: -0.12506668 | I11: =0.3644*H11 - 0.0953 -> -0.1408743 | L11: -0.39263276 | M11: -0.60379103 | N11: =0.3461*M11 - 0.285 -> -0.49397208
B12: 0.27253333 | C12: -1.6753571 | D12: =0.661*C12 + 0.9972 -> -0.11021104 | G12: 0.032334462 | H12: 0.89764391 | I12: =0.3644*H12 - 0.0953 -> 0.23180144 | L12: -0.2425 | M12: -0.46780872 | N12: =0.3461*M12 - 0.285 -> -0.4469086
B13: 0.51273219 | C13: -0.38193885 | D13: =0.661*C13 + 0.9972 -> 0.74473842 | G13: 0.14319548 | H13: -0.1154419 | I13: =0.3644*H13 - 0.0953 -> -0.13736703 | L13: -0.41110959 | M13: -1.5533018 | N13: =0.3461*M13 - 0.285 -> -0.82259776
B14: 0.60511637 | C14: 0.91688682 | D14: =0.661*C14 + 0.9972 -> 1.6032622 | G14: 0.5681627 | H14: -0.033097426 | I14: =0.3644*H14 - 0.0953 -> -0.1073607 | L14: -0.37415592 | M14: -0.82486064 | N14: =0.3461*M14 - 0.285 -> -0.57048427
... B17: 2.9331977 | C17: 1.3282425 | D17: =0.661*C17 + 0.9972 -> 1.8751683 | G17: 1.8061107 | H17: 4.2143055 | I17: =0.3644*H17 - 0.0953 -> 1.4403929 | L17: 0.21710282 | M17: 2.2355927 | N17: =0.3461*M17 - 0.285 -> 0.48873865
B18: 0244E3 | D18: =CORREL(B3:B17,C3:C17)*100 -> 82.977436 | G18: 2.6006146 | H18: 6.4124339 | I18: =0.3644*H18 - 0.0953 -> 2.2413909 | L18: 0.32796383 | M18: 0.81238473 | N18: =0.3461*M18 - 0.285 -> -0.0038336465
G19: 0374E4 | I19: =CORREL(H3:H18,G3:G18)*100 -> 89.943067 | L19: 0.5681627 | M19: 1.1704609 | N19: =0.3461*M19 - 0.285 -> 0.12009652
L20: 0.80836156 | M20: 0.89337861 | N20: =0.3461*M20 - 0.285 -> 0.024198338
L21: 1.2333288 | M21: 3.602583 | N21: =0.3461*M21 - 0.285 -> 0.96185397
L22: 1.3072361 | M22: 3.0392662 | N22: =0.3461*M22 - 0.285 -> 0.76689003
L23: 2.4527999 | M23: 5.9347784 | N23: =0.3461*M23 - 0.285 -> 1.7690268
L24: 0533E2 | N24: =CORREL(M3:M23,L3:L23)*100 -> 79.957074
B26: RC calculus
B28: Considérant le VB av
B29: Fact1 | C29: Fact2 | D29: Fact3 | H29: Fact4 bis | I29: %info
A30: Fp av | B30: -0.7058 | C30: 0.3825 | D30: 0.5963 | H30: =D30/SUM(D30:D32) -> 0.90871685 | I30: =H30*D38 -> 80.727376
A31: Fpn av | B31: 0.0035 | C31: 0.8436 | D31: -0.5369 | H31: =D31/SUM(D30:D32) -> -0.81819567 | I31: =H31*D38 -> -72.685776
A32: R av | B32: 0.7084 | C32: 0.3769 | D32: 0.5968 | H32: =D32/SUM(D30:D32) -> 0.90947882 | I32: =H32*D38 -> 80.795067
B35: Vecteurs propres
A37: Eval | B37: 0.0093 | C37: 0.3256 | D37: 2.6651
A38: info % | B38: =B37/SUM(B37:D37)*100 -> 0.31 | C38: =(C37/SUM(B37:D37))*100 -> 10.853333 | D38: =D37/SUM(B37:D37)*100 -> 88.836667
B39: Valeurs propres
A43: RC=0,807*Fp av-0,727*Fpn av+0,808*Rav
C46: Fp av | D46: Fpn av | E46: R av
B47: Fp av | C47: 1 | D47: -0.7483 | E47: 0.9907
B48: Fpn av | C48: -0.7483 | D48: 1 | E48: -0.7504
B49: R av | C49: 0.9907 | D49: -0.7504 | E49: 1
B52: Matrice réduite
G56: VB max= f(CP) = x(insert)*RC - y(insert)
Q57: !Voir courbes_corr_vbmax
...

