Workbook

Sheet résultats
B5: Trial | C5: Edge | D5: NC | E5: N av | F5: N max | G5: Fpav | H5: Fpmax | I5: Fs av | J5: Fs max | K5: Fpnav | L5: Fpn max | M5: P av | N5: P max | O5: Fz av | P5: Fz max | Q5: R av | R5: R max | S5: EAA av | T5: EAA max | U5: λ av | V5: λ max | W5: η | X5: μe | Y5: β | Z5: VB max | AA5: VB av | AB5: Rt | AC5: Ra | AD5: Curve
B6: N° | C6: ref | D6: rev | E6: N | F6: N | G6: N | H6: N | I6: N | J6: N | K6: N | L6: N | M6: N | N6: N | O6: N | P6: N | Q6: N | R6: N | S6: ° | T6: ° | U6: ° | V6: ° | W6: ° | Y6: ° | Z6: µm | AA6: µm | AB6: µm | AC6: µm | AD6: µm
A7: Results | B7: 1 | C7: 0025E2 | D7: 139 | E7: 271.52 | F7: 502.26 | G7: 386.35 | H7: 597.05 | I7: 474.83 | J7: 777.8 | K7: -55.64 | L7: -98.48 | M7: 390.34 | N7: 605.12 | O7: 126.88 | P7: 170.1 | Q7: 466.83 | R7: 782.67 | S7: 71.97 | T7: 78.21 | U7: 6.5 | V7: 7.72 | W7: -81.8 | X7: 1.44 | Y7: 55.18 | Z7: - | AA7: - | AB7: - | AC7: - | AD7: -
C8: 0025E4 | D8: 139 | E8: 266.43 | F8: 490.45 | G8: 407.52 | H8: 626.97 | I8: 489.52 | J8: 791.8 | K8: -61.51 | L8: -109.82 | M8: 412.14 | N8: 636.52 | O8: 138.79 | P8: 190.25 | Q8: 493.41 | R8: 796.98 | S8: 71.27 | T8: 77.2 | U8: 7.13 | V8: 8.84 | W8: -81.42 | X8: 1.55 | Y8: 57.12 | Z8: - | AA8: - | AB8: 1.074 | AC8: 0.162 | AD8: -1.6284
C9: 0244E1 | D9: 139 | E9: 274.47 | F9: 515.93 | G9: 374.88 | H9: 594.79 | I9: 467.01 | J9: 782.57 | K9: -57.02 | L9: -105.37 | M9: 379.19 | N9: 604.05 | O9: 117.33 | P9: 155.15 | Q9: 470.5 | R9: 789.03 | S9: 72.74 | T9: 79.45 | U9: 6.75 | V9: 8.16 | W9: -81.35 | X9: 1.38 | Y9: 54.1 | Z9: - | AA9: - | AB9: 1.588 | AC9: 0.1775 | AD9: -1.613
C10: 0374E3 | D10: 139 | E10: - | F10: - | G10: - | H10: - | I10: - | J10: - | K10: - | L10: - | M10: - | N10: - | O10: - | P10: - | Q10: - | R10: - | S10: - | T10: - | U10: - | V10: - | W10: - | X10: - | Y10: - | Z10: - | AA10: - | AB10: - | AC10: - | AD10: - | AE10: -
C11: 0429E2 | D11: 139 | E11: 263.81 | F11: 498.2 | G11: 401.54 | H11: 617.38 | I11: 483.75 | J11: 793.32 | K11: -60.19 | L11: -104.19 | M11: 406.03 | N11: 626.11 | O11: 136.59 | P11: 179.27 | Q11: 487.53 | R11: 799.43 | S11: 70.84 | T11: 77.77 | U11: 6.87 | V11: 8.77 | W11: -81.47 | X11: 1.54 | Y11: 56.99 | Z11: - | AA11: - | AB11: - | AC11: - | AD11: -
C12: 0429E4 | D12: 139 | E12: 269.1 | F12: 492.94 | G12: 413.16 | H12: 631.94 | I12: 465.62 | J12: 800.23 | K12: -64.09 | L12: -110.05 | M12: 418.1 | N12: 641.45 | O12: 139.91 | P12: 195.28 | Q12: 499.83 | R12: 806.25 | S12: 71.43 | T12: 76.95 | U12: 7.43 | V12: 9.35 | W12: -81.18 | X12: 1.55 | Y12: 57.23 | Z12: - | AA12: - | AB12: 1.66 | AC12: 0.208 | AD12: -1.86325
C13: 0532E1 | D13: 139 | E13: 272.16 | F13: 503.32 | G13: 411.66 | H13: 637 | I13: 496.29 | J13: 806.61 | K13: -59.2 | L13: -111.66 | M13: 415.89 | N13: 646.71 | O13: 141.11 | P13: 189.71 | Q13: 499.83 | R13: 814.78 | S13: 71.15 | T13: 77.16 | U13: 6.82 | V13: 8.48 | W13: -81.82 | X13: 1.53 | Y13: 56.8 | Z13: - | AA13: - | AB13: 1.47 | AC13: 0.1575 | AD13: -1.7962
C14: 0532E4 | D14: 139 | E14: 270.4 | F14: 492.97 | G14: 292.13 | H14: 601.93 | I14: 478.98 | J14: 777.39 | K14: -54.81 | L14: -101.11 | M14: 297.23 | N14: 610.36 | O14: 131.66 | P14: 178.66 | Q14: 482.14 | R14: 782.1 | S14: 71.67 | T14: 77.79 | U14: 6.51 | V14: 8.34 | W14: -79.37 | X14: 1.1 | Y14: 47.71 | Z14: - | AA14: - | AB14: - | AC14: - | AD14: -
C15: 0575E2 | D15: 139 | E15: - | F15: - | G15: - | H15: - | I15: - | J15: - | K15: - | L15: - | M15: - | N15: - | O15: - | P15: - | Q15: - | R15: - | S15: - | T15: - | U15: - | V15: - | W15: - | X15: - | Y15: - | Z15: - | AA15: - | AB15: - | AC15: - | AD15: - | AE15: -
C16: 0575E4 | D16: 139 | E16: 269.64 | F16: 503.02 | G16: 416.03 | H16: 643.79 | I16: 499 | J16: 814.15 | K16: -60.28 | L16: -108.32 | M16: 420.37 | N16: 652.84 | O16: 144.16 | P16: 196.65 | Q16: 502.66 | R16: 820.37 | S16: 70.82 | T16: 77.95 | U16: 6.99 | V16: 9.91 | W16: -81.76 | X16: 1.56 | Y16: 57.32 | Z16: - | AA16: - | AB16: - | AC16: - | AD16: -
C17: 0639E1 | D17: 139 | E17: 259.27 | F17: 474.72 | G17: 371.1 | H17: 571.87 | I17: 455.13 | J17: 736.61 | K17: -51.95 | L17: -92.49 | M17: 374.72 | N17: 579.3 | O17: 123.39 | P17: 162.84 | Q17: 458.11 | R17: 741.91 | S17: 71.86 | T17: 77.67 | U17: 6.5 | V17: 7.56 | W17: -82.03 | X17: 1.45 | Y17: 55.32 | Z17: - | AA17: - | AB17: - | AC17: - | AD17: -
C18: 0639E4 | D18: 139 | E18: 281.93 | F18: 531.71 | G18: 416.32 | H18: 644.9 | I18: 506.08 | J18: 831.14 | K18: -54.71 | L18: -101.19 | M18: 419.9 | N18: 652.79 | O18: 143.85 | P18: 189.03 | Q18: 509.04 | R18: 836.2 | S18: 70.82 | T18: 77.99 | U18: 6.21 | V18: 7.7 | W18: -82.51 | X18: 1.49 | Y18: 56.12 | Z18: - | AA18: - | AB18: - | AC18: - | AD18: -
C19: 0699E2 | D19: 139 | E19: 278.88 | F19: 507.95 | G19: 397.42 | H19: 617.08 | I19: 487.71 | J19: 798.92 | K19: -62.63 | L19: -110.31 | M19: 402.32 | N19: 626.86 | O19: 127.07 | P19: 174.75 | Q19: 491.76 | R19: 804.92 | S19: 72.75 | T19: 78.2 | U19: 7.34 | V19: 8.95 | W19: -81.04 | X19: 1.44 | Y19: 55.27 | Z19: - | AA19: - | AB19: 0.996 | AC19: 0.102 | AD19: -1.925
C20: 0699E3 | D20: 139 | E20: 285.4 | F20: 522.13 | G20: 411.06 | H20: 638.14 | I20: 503.02 | J20: 824.52 | K20: -65.36 | L20: -114.43 | M20: 416.22 | N20: 648.32 | O20: 132.09 | P20: 180.86 | Q20: 507.29 | R20: 830.23 | S20: 72.48 | T20: 78.16 | U20: 7.48 | V20: 10.19 | W20: -80.97 | X20: 1.46 | Y20: 55.56 | Z20: - | AA20: - | AB20: - | AC20: - | AD20: -
B21: 2 | C21: 0025E2 | D21: 11389 | E21: 265.8 | F21: 496.95 | G21: 424.66 | H21: 643.76 | I21: 504.31 | J21: 809.18 | K21: -61.28 | L21: -109.27 | M21: 429.06 | N21: 652.97 | O21: 150.54 | P21: 195.12 | Q21: 508.14 | R21: 815.06 | S21: 70.25 | T21: 76.52 | U21: 6.72 | V21: 8.34 | W21: -81.79 | X21: 1.61 | Y21: 58.22 | Z21: 24.72 | AA21: 21.17 | AB21: - | AC21: - | AD21: -
C22: 0025E4 | D22: 11389 | E22: 270.18 | F22: 505.57 | G22: 427.17 | H22: 653.59 | I22: 508.65 | J22: 823.86 | K22: -58.88 | L22: -111.33 | M22: 431.21 | N22: 663 | O22: 152.31 | P22: 200.43 | Q22: 512.08 | R22: 830.24 | S22: 70 | T22: 78.28 | U22: 6.42 | V22: 8.91 | W22: -82.15 | X22: 1.6 | Y22: 57.93 | Z22: 35.86 | AA22: 24.17 | AB22: - | AC22: - | AD22: -
C23: 0244E1 | D23: 11389 | E23: 267.63 | F23: 493.22 | G23: 387.27 | H23: 590.27 | I23: 473.47 | J23: 765.56 | K23: -55.18 | L23: -93.79 | M23: 391.18 | N23: 597.67 | O23: 129.13 | P23: 173.21 | Q23: 476.75 | R23: 769.77 | S23: 71.94 | T23: 77.49 | U23: 6.7 | V23: 8.53 | W23: -81.89 | X23: 1.46 | Y23: 55.62 | Z23: 26.12 | AA23: 16.73 | AB23: - | AC23: - | AD23: -
C24: 0374E3 | D24: 11389 | E24: 265.04 | F24: 502.79 | G24: 389.03 | H24: 613.35 | I24: 473.02 | J24: 785.23 | K24: -66.4 | L24: -144.46 | M24: 394.66 | N24: 630.13 | O24: 123.72 | P24: 197.31 | Q24: 477.89 | R24: 795.55 | S24: 72.92 | T24: 80.46 | U24: 7.99 | V24: 14.93 | W24: -80.31 | X24: 1.49 | Y24: 56.12 | Z24: 19.62 | AA24: 19 | AB24: 2.6 | AC24: 0.256 | AD24: -1.4232
C25: 0429E2 | D25: 11389 | E25: 261.93 | F25: 498.92 | G25: 423.83 | H25: 640.3 | I25: 502.39 | J25: 805.57 | K25: -61.35 | L25: -103.25 | M25: 428.25 | N25: 648.57 | O25: 151.27 | P25: 194.85 | Q25: 506.19 | R25: 811.17 | S25: 69.74 | T25: 76.81 | U25: 6.85 | V25: 10.03 | W25: -81.76 | X25: 1.63 | Y25: 58.55 | Z25: 71.18 | AA25: - | AB25: - | AC25: - | AD25: - | AE25: -
C26: 0429E4 | D26: 11389 | E26: 271.13 | F26: 503.35 | G26: 440.18 | H26: 660.12 | I26: 520.43 | J26: 826.37 | K26: -64.97 | L26: -111.65 | M26: 444.95 | N26: 669.5 | O26: 156.58 | P26: 206.84 | Q26: 524.55 | R26: 831.58 | S26: 70.08 | T26: 76.19 | U26: 7.05 | V26: 9.49 | W26: -81.6 | X26: 1.64 | Y26: 58.64 | Z26: 36.54 | AA26: 30.49 | AB26: 2.908 | AC26: 0.354 | AD26: -1.974
C27: 0532E1 | D27: 11389 | E27: 270.58 | F27: 501.01 | G27: 425.92 | H27: 655.01 | I27: 507.56 | J27: 819.87 | K27: -55.47 | L27: -99.02 | M27: 429.52 | N27: 662.45 | O27: 153.61 | P27: 210.89 | Q27: 510.68 | R27: 823.8 | S27: 69.92 | T27: 75.8 | U27: 6.11 | V27: 7.9 | W27: -82.58 | X27: 1.59 | Y27: 57.79 | Z27: 31.47 | AA27: 26.63 | AB27: - | AC27: - | AD27: -
C28: 0532E4 | D28: 11389 | E28: 265.61 | F28: 493.27 | G28: 423.26 | H28: 635.03 | I28: 503.46 | J28: 800.03 | K28: -51.15 | L28: -90.14 | M28: 426.34 | N28: 641.4 | O28: 156.41 | P28: 205.88 | Q28: 506.14 | R28: 803.82 | S28: 69.38 | T28: 75.73 | U28: 5.75 | V28: 8.4 | W28: -83.11 | X28: 1.61 | Y28: 58.08 | Z28: 41.14 | AA28: 33.25 | AB28: - | AC28: - | AD28: -
C29: 0575E2 | D29: 11389 | E29: 278.81 | F29: 520.05 | G29: 431.02 | H29: 655.09 | I29: 516.9 | J29: 835.93 | K29: -56.99 | L29: -98.23 | M29: 434.77 | N29: 662.41 | O29: 153.17 | P29: 210.52 | Q29: 520.22 | R29: 839.32 | S29: 70.47 | T29: 76.38 | U29: 6.5 | V29: 9.23 | W29: -82.47 | X29: 1.56 | Y29: 57.33 | Z29: 32.1 | AA29: 29.6 | AB29: - | AC29: - | AD29: -
C30: 0575E4 | D30: 11389 | E30: 270.46 | F30: 504.13 | G30: 440.95 | H30: 659.87 | I30: 521.03 | J30: 822.88 | K30: -58.9 | L30: -103.59 | M30: 444.87 | N30: 667.95 | O30: 161.35 | P30: 214.33 | Q30: 524.42 | R30: 827.26 | S30: 69.56 | T30: 75.93 | U30: 6.49 | V30: 8.78 | W30: -82.39 | X30: 1.64 | Y30: 58.7 | Z30: 32.25 | AA30: 28.33 | AB30: - | AC30: - | AD30: -
C31: 0639E1 | D31: 11389 | E31: 257.91 | F31: 478.6 | G31: 401.17 | H31: 600.56 | I31: 480.32 | J31: 765.25 | K31: -51.65 | L31: -88.91 | M31: 404.48 | N31: 607.11 | O31: 144.03 | P31: 184.64 | Q31: 483.13 | R31: 769.18 | S31: 70.04 | T31: 76.43 | U31: 6.12 | V31: 8.03 | W31: -82.66 | X31: 1.57 | Y31: 57.48 | Z31: 54.74 | AA31: 19.08 | AB31: - | AC31: - | AD31: -
C32: 0639E4 | D32: 11389 | E32: 279.43 | F32: 521.98 | G32: 449.49 | H32: 678.56 | I32: 533.21 | J32: 851.67 | K32: -61.73 | L32: -104.53 | M32: 453.71 | N32: 686.56 | O32: 162.08 | P32: 212.43 | Q32: 536.87 | R32: 856.14 | S32: 69.8 | T32: 76.04 | U32: 6.61 | V32: 9.44 | W32: -82.18 | X32: 1.62 | Y32: 58.37 | Z32: 45.32 | AA32: 29.56 | AB32: - | AC32: - | AD32: -
C33: 0699E2 | D33: 11389 | E33: 278.68 | F33: 514.12 | G33: 427.19 | H33: 648.19 | I33: 513.03 | J33: 822.11 | K33: -62.87 | L33: -109.68 | M33: 431.79 | N33: 657.4 | O33: 146.76 | P33: 195.23 | Q33: 516.93 | R33: 827.92 | S33: 71.05 | T33: 76.99 | U33: 6.98 | V33: 9.17 | W33: -81.63 | X33: 1.55 | Y33: 57.16 | Z33: 26.15 | AA33: 20.06 | AB33: - | AC33: - | AD33: -
C34: 0699E3 | D34: 11389 | E34: 286.24 | F34: 529.61 | G34: 434.71 | H34: 665.72 | I34: 523.61 | J34: 846.95 | K34: -63.78 | L34: -112.81 | M34: 439.36 | N34: 675.21 | O34: 148.57 | P34: 199.81 | Q34: 527.55 | R34: 852.72 | S34: 71.14 | T34: 77.18 | U34: 6.93 | V34: 9.28 | W34: -81.65 | X34: 1.53 | Y34: 56.92 | Z34: 24.16 | AA34: 18.47 | AB34: - | AC34: - | AD34: -
B35: 3 | C35: 0025E2 | D35: =D21+11111+139 -> 22639 | E35: 262.31 | F35: 484.75 | G35: 397.74 | H35: 604.84 | I35: 479.64 | J35: 772.32 | K35: -41.06 | L35: -83.22 | M35: 399.85 | N35: 610.54 | O35: 147.29 | P35: 190.49 | Q35: 481.43 | R35: 775.99 | S35: 69.39 | T35: 77.41 | U35: 4.6 | V35: 6.79 | W35: -84.11 | X35: 1.52 | Y35: 56.73 | Z35: 28.68 | AA35: 23.89 | AB35: - | AC35: - | AD35: -
C36: 0025E4 | D36: =D22+11111+139 -> 22639 | E36: 265.39 | F36: 492.82 | G36: 435.73 | H36: 659.35 | I36: 513.44 | J36: 820.82 | K36: -59.13 | L36: -102.31 | M36: 439.72 | N36: 667.24 | O36: 159.47 | P36: 215.28 | Q36: 516.97 | R36: 824.81 | S36: 69.59 | T36: 75.63 | U36: 6.49 | V36: 8.36 | W36: -82.27 | X36: 1.66 | Y36: 58.89 | Z36: 45.47 | AA36: 28.76 | AB36: 2.46 | AC36: 0.28 | AD36: -2.297
C37: 0244E1 | D37: =D23+11111+139 -> 22639 | E37: 267.29 | F37: 491.96 | G37: 384.48 | H37: 583.76 | I37: 471.17 | J37: 758.99 | K37: -54.06 | L37: -91.97 | M37: 388.26 | N37: 590.96 | O37: 128.13 | P37: 166.96 | Q37: 474.3 | R37: 763.68 | S37: 71.78 | T37: 77.74 | U37: 6.54 | V37: 8.61 | W37: -82 | X37: 1.45 | Y37: 55.46 | Z37: 35.74 | AA37: 19.84 | AB37: 2.428 | AC37: 0.296 | AD37: -1.8866
C38: 0374E3 | D38: =D24+11111+139 -> 22639 | E38: 262.97 | F38: 500.46 | G38: 392.5 | H38: 617.1 | I38: 475.2 | J38: 794.45 | K38: -63.17 | L38: -140 | M38: 397.55 | N38: 632.78 | O38: 128.89 | P38: 204.32 | Q38: 479.63 | R38: 800.69 | S38: 71.97 | T38: 80.21 | U38: 7.38 | V38: 11.74 | W38: -80.86 | X38: 1.51 | Y38: 56.52 | Z38: 30.98 | AA38: 25.4 | AB38: 4.534 | AC38: 392 | AD38: -1.7316
C39: 0429E2 | D39: =D25+11111+139 -> 22639 | E39: 259.08 | F39: 496.95 | G39: 420.49 | H39: 641.7 | I39: 497.74 | J39: 808.67 | K39: -61.42 | L39: -106.68 | M39: 424.95 | N39: 650.51 | O39: 149.98 | P39: 195.17 | Q39: 501.59 | R39: 814 | S39: 69.38 | T39: 76.77 | U39: 6.53 | V39: 8.66 | W39: -81.69 | X39: 1.64 | Y39: 58.63 | Z39: 76.64 | AA39: 38.2 | AB39: - | AC39: - | AD39: -
C40: 0429E4 | D40: =D26+11111+139 -> 22639 | E40: 270.43 | F40: 505.73 | G40: 445.91 | H40: 668.42 | I40: 525.29 | J40: 830.32 | K40: -65.55 | L40: -113.16 | M40: 450.7 | N40: 677.93 | O40: 160.25 | P40: 207.92 | Q40: 529.42 | R40: 837.59 | S40: 69.79 | T40: 76.2 | U40: 7.06 | V40: 10.46 | W40: -81.64 | X40: 1.67 | Y40: 59.04 | Z40: 54.29 | AA40: 38.55 | AB40: - | AC40: - | AD40: -
C41: 0532E1 | D41: =D27+11111+139 -> 22639 | E41: 281.39 | F41: 525.58 | G41: 444.06 | H41: 670.97 | I41: 529.41 | J41: 848.21 | K41: -58.18 | L41: -103.79 | M41: 447.86 | N41: 678.95 | O41: 160.16 | P41: 207.52 | Q41: 532.63 | R41: 853.64 | S41: 69.48 | T41: 77.15 | U41: 5.96 | V41: 7.33 | W41: -82.54 | X41: 1.59 | Y41: 57.86 | Z41: 41.89 | AA41: 28.98 | AB41: 3.434 | AC41: 0.386 | AD41: -2.2126
C42: 0532E4 | D42: =D28+11111+139 -> 22639 | E42: 263.62 | F42: 498.81 | G42: 418.9 | H42: 642.25 | I42: 498.66 | J42: 810.78 | K42: -50.2 | L42: -95.13 | M42: 421.9 | N42: 649.26 | O42: 154.82 | P42: 206.79 | Q42: 501.26 | R42: 815.18 | S42: 68.92 | T42: 75.92 | U42: 5.42 | V42: 7.41 | W42: -83.17 | X42: 1.6 | Y42: 58 | Z42: 41.63 | AA42: 34.63 | AB42: - | AC42: - | AD42: -
C43: 0575E2 | D43: =D29+11111+139 -> 22639 | E43: 277.66 | F43: 523.29 | G43: 435.45 | H43: 665.61 | I43: 520.23 | J43: 841.82 | K43: -59.8 | L43: -107.22 | M43: 439.54 | N43: 674.19 | O43: 154.64 | P43: 211.27 | Q43: 523.86 | R43: 846.47 | S43: 70.39 | T43: 76.56 | U43: 6.69 | V43: 9.72 | W43: -82.18 | X43: 1.58 | Y43: 57.72 | Z43: 40.2 | AA43: 37.46 | AB43: 2.398 | AC43: 0.314 | AD43: -1.6916
C44: 0575E4 | D44: =D30+11111+139 -> 22639 | E44: 268.26 | F44: 499.33 | G44: 452.25 | H44: 673.29 | I44: 529.94 | J44: 833.94 | K44: -62.41 | L44: -107.95 | M44: 456.54 | N44: 681.89 | O44: 167.28 | P44: 219.73 | Q44: 533.73 | R44: 839.34 | S44: 69.24 | T44: 75.58 | U44: 6.75 | V44: 9.8 | W44: -82.14 | X44: 1.7 | Y44: 59.56 | Z44: 44.5 | AA44: 35.61 | AB44: - | AC44: - | AD44: -
...

Sheet reduite
B1: Trial | C1: Edge | D1: NC | E1: N av | F1: N max | G1: Fp av | H1: Fp max | I1: Fs av | J1: Fs max | K1: Fpn av | L1: Fpn max | M1: Fz av | N1: Fz max | O1: R av | P1: R max | Q1: EAA av | R1: EAA max | S1: λ av | T1: λ max | U1: η | V1: μe | W1: β | X1: VB max | Y1: VB av | Z1: Rt | AA1: Ra | AB1: Curve | AD1: RC
B2: N° | C2: ref | D2: rev
A3: Centered Matrix | B3: 1 | C3: 0025E2 | D3: 139 | E3: =(résultats!E7-résultats!E161)/résultats!E162 -> 0.13117438 | F3: =(résultats!F7-résultats!F161)/résultats!F162 -> -0.20324589 | G3: =(résultats!G7-résultats!G161)/résultats!G162 -> -0.96043529 | H3: =(résultats!H7-résultats!H161)/résultats!H162 -> -0.88422386 | I3: =(résultats!I7-résultats!I161)/résultats!I162 -> -0.9141969 | J3: =(résultats!J7-résultats!J161)/résultats!J162 -> -0.8414997 | K3: =(résultats!K7-résultats!K161)/résultats!K162 -> 0.38097318 | L3: =(résultats!L7-résultats!L161)/résultats!L162 -> 0.50134683 | M3: =(résultats!O7-résultats!O161)/résultats!O162 -> -1.0133808 | N3: =(résultats!P7-résultats!P161)/résultats!P162 -> -0.91831806 | O3: =(résultats!Q7-résultats!Q161)/résultats!Q162 -> -1.0470257 | P3: =(résultats!R7-résultats!R161)/résultats!R162 -> -0.83569198 | Q3: =(résultats!S7-résultats!S161)/résultats!S162 -> 1.016998 | R3: =(résultats!T7-résultats!T161)/résultats!T162 -> 1.1397718 | S3: =(résultats!U7-résultats!U161)/résultats!U162 -> -0.39971691 | T3: =(résultats!V7-résultats!V161)/résultats!V162 -> -0.93897707 | ... W3: =(résultats!Y7-résultats!Y161)/résultats!Y162 -> -0.29412152 | X3: - | Y3: - | Z3: - | AA3: - | AB3: -
C4: 0025E4 | D4: 139 | E4: =(résultats!E8-résultats!E161)/résultats!E162 -> -0.027409533 | F4: =(résultats!F8-résultats!F161)/résultats!F162 -> -0.42719562 | G4: =(résultats!G8-résultats!G161)/résultats!G162 -> -0.74256438 | H4: =(résultats!H8-résultats!H161)/résultats!H162 -> -0.67872484 | I4: =(résultats!I8-résultats!I161)/résultats!I162 -> -0.74898522 | J4: =(résultats!J8-résultats!J161)/résultats!J162 -> -0.73440578 | K4: =(résultats!K8-résultats!K161)/résultats!K162 -> 0.18630977 | L4: =(résultats!L8-résultats!L161)/résultats!L162 -> 0.27595733 | M4: =(résultats!O8-résultats!O161)/résultats!O162 -> -0.7922197 | N4: =(résultats!P8-résultats!P161)/résultats!P162 -> -0.6582825 | O4: =(résultats!Q8-résultats!Q161)/résultats!Q162 -> -0.75172837 | P4: =(résultats!R8-résultats!R161)/résultats!R162 -> -0.72955905 | Q4: =(résultats!S8-résultats!S161)/résultats!S162 -> 0.79451822 | R4: =(résultats!T8-résultats!T161)/résultats!T162 -> 0.68183213 | S4: =(résultats!U8-résultats!U161)/résultats!U162 -> 0.11118886 | T4: =(résultats!V8-résultats!V161)/résultats!V162 -> -0.50256109 | ... W4: =(résultats!Y8-résultats!Y161)/résultats!Y162 -> -0.15077957 | X4: - | Y4: - | Z4: =(résultats!AB8-résultats!AB161)/résultats!AB162 -> -1.5081543 | AA4: =(résultats!AC8-résultats!AC161)/résultats!AC162 -> -0.16428662 | AB4: =(résultats!AD8-résultats!AD161)/résultats!AD162 -> 0.38605292
C5: 0244E1 | D5: 139 | E5: =(résultats!E9-résultats!E161)/résultats!E162 -> 0.2230845 | F5: =(résultats!F9-résultats!F161)/résultats!F162 -> 0.055974503 | G5: =(résultats!G9-résultats!G161)/résultats!G162 -> -1.0784787 | H5: =(résultats!H9-résultats!H161)/résultats!H162 -> -0.89974618 | I5: =(résultats!I9-résultats!I161)/résultats!I162 -> -1.0021448 | J5: =(résultats!J9-résultats!J161)/résultats!J162 -> -0.80501127 | K5: =(résultats!K9-résultats!K161)/résultats!K162 -> 0.33520904 | L5: =(résultats!L9-résultats!L161)/résultats!L162 -> 0.36440383 | M5: =(résultats!O9-résultats!O161)/résultats!O162 -> -1.1907182 | N5: =(résultats!P9-résultats!P161)/résultats!P162 -> -1.1112477 | O5: =(résultats!Q9-résultats!Q161)/résultats!Q162 -> -1.0062529 | P5: =(résultats!R9-résultats!R161)/résultats!R162 -> -0.78852179 | Q5: =(résultats!S9-résultats!S161)/résultats!S162 -> 1.2617258 | R5: =(résultats!T9-résultats!T161)/résultats!T162 -> 1.7019948 | S5: =(résultats!U9-résultats!U161)/résultats!U162 -> -0.19697653 | T5: =(résultats!V9-résultats!V161)/résultats!V162 -> -0.76752794 | ... W5: =(résultats!Y9-résultats!Y161)/résultats!Y162 -> -0.37392013 | X5: - | Y5: - | Z5: =(résultats!AB9-résultats!AB161)/résultats!AB162 -> -1.1900417 | AA5: =(résultats!AC9-résultats!AC161)/résultats!AC162 -> -0.16403943 | AB5: =(résultats!AD9-résultats!AD161)/résultats!AD162 -> 0.43456447
C6: 0374E3 | D6: 139 | E6: - | F6: - | G6: - | H6: - | I6: - | J6: - | K6: - | L6: - | M6: - | N6: - | O6: - | P6: - | Q6: - | R6: - | S6: - | T6: - | U6: - | V6: - | W6: - | X6: - | Y6: - | Z6: - | AA6: - | AB6: - | AC6: - | AE6: - | AF6: - | AG6: - | AH6: -
C7: 0429E2 | D7: 139 | E7: =(résultats!E11-résultats!E161)/résultats!E162 -> -0.10903819 | F7: =(résultats!F11-résultats!F161)/résultats!F162 -> -0.28023453 | G7: =(résultats!G11-résultats!G161)/résultats!G162 -> -0.80410751 | H7: =(résultats!H11-résultats!H161)/résultats!H162 -> -0.74459167 | I7: =(résultats!I11-résultats!I161)/résultats!I162 -> -0.81387775 | J7: =(résultats!J11-résultats!J161)/résultats!J162 -> -0.72277843 | K7: =(résultats!K11-résultats!K161)/résultats!K162 -> 0.23008417 | L7: =(résultats!L11-résultats!L161)/résultats!L162 -> 0.38785705 | M7: =(résultats!O11-résultats!O161)/résultats!O162 -> -0.8330723 | N7: =(résultats!P11-résultats!P161)/résultats!P162 -> -0.7999793 | O7: =(résultats!Q11-résultats!Q161)/résultats!Q162 -> -0.81705374 | P7: =(résultats!R11-résultats!R161)/résultats!R162 -> -0.71138814 | Q7: =(résultats!S11-résultats!S161)/résultats!S162 -> 0.65785205 | R7: =(résultats!T11-résultats!T161)/résultats!T162 -> 0.94027333 | S7: =(résultats!U11-résultats!U161)/résultats!U162 -> -0.099661141 | T7: =(résultats!V11-résultats!V161)/résultats!V162 -> -0.52983709 | ... W7: =(résultats!Y11-résultats!Y161)/résultats!Y162 -> -0.16038495 | X7: - | Y7: - | Z7: - | AA7: - | AB7: -
C8: 0429E4 | D8: 139 | E8: =(résultats!E12-résultats!E161)/résultats!E162 -> 0.055776919 | F8: =(résultats!F12-résultats!F161)/résultats!F162 -> -0.37997844 | G8: =(résultats!G12-résultats!G161)/résultats!G162 -> -0.68452036 | H8: =(résultats!H12-résultats!H161)/résultats!H162 -> -0.64458947 | I8: =(résultats!I12-résultats!I161)/résultats!I162 -> -1.0177775 | J8: =(résultats!J12-résultats!J161)/résultats!J162 -> -0.66991993 | K8: =(résultats!K12-résultats!K161)/résultats!K162 -> 0.10075072 | L8: =(résultats!L12-résultats!L161)/résultats!L162 -> 0.27138594 | M8: =(résultats!O12-résultats!O161)/résultats!O162 -> -0.77142201 | N8: =(résultats!P12-résultats!P161)/résultats!P162 -> -0.5933704 | O8: =(résultats!Q12-résultats!Q161)/résultats!Q162 -> -0.68040374 | P8: =(résultats!R12-résultats!R161)/résultats!R162 -> -0.66080626 | Q8: =(résultats!S12-résultats!S161)/résultats!S162 -> 0.84537075 | R8: =(résultats!T12-résultats!T161)/résultats!T162 -> 0.56848072 | S8: =(résultats!U12-résultats!U161)/résultats!U162 -> 0.35447732 | T8: =(résultats!V12-résultats!V161)/résultats!V162 -> -0.30383595 | ... W8: =(résultats!Y12-résultats!Y161)/résultats!Y162 -> -0.14265193 | X8: - | Y8: - | Z8: =(résultats!AB12-résultats!AB161)/résultats!AB162 -> -1.1454812 | AA8: =(résultats!AC12-résultats!AC161)/résultats!AC162 -> -0.163553 | AB8: =(résultats!AD12-résultats!AD161)/résultats!AD162 -> -0.35374823
C9: 0532E1 | D9: 139 | E9: =(résultats!E13-résultats!E161)/résultats!E162 -> 0.1511142 | F9: =(résultats!F13-résultats!F161)/résultats!F162 -> -0.1831454 | G9: =(résultats!G13-résultats!G161)/résultats!G162 -> -0.6999576 | H9: =(résultats!H13-résultats!H161)/résultats!H162 -> -0.60983596 | I9: =(résultats!I13-résultats!I161)/résultats!I162 -> -0.67284614 | J9: =(résultats!J13-résultats!J161)/résultats!J162 -> -0.6211157 | K9: =(résultats!K13-résultats!K161)/résultats!K162 -> 0.26291496 | L9: =(résultats!L13-résultats!L161)/résultats!L162 -> 0.2393862 | M9: =(résultats!O13-résultats!O161)/résultats!O162 -> -0.74913877 | N9: =(résultats!P13-résultats!P161)/résultats!P162 -> -0.6652512 | O9: =(résultats!Q13-résultats!Q161)/résultats!Q162 -> -0.68040374 | P9: =(résultats!R13-résultats!R161)/résultats!R162 -> -0.59754184 | Q9: =(résultats!S13-résultats!S161)/résultats!S162 -> 0.75637882 | R9: =(résultats!T13-résultats!T161)/résultats!T162 -> 0.6636959 | S9: =(résultats!U13-résultats!U161)/résultats!U162 -> -0.14020922 | T9: =(résultats!V13-résultats!V161)/résultats!V162 -> -0.64283765 | ... W9: =(résultats!Y13-résultats!Y161)/résultats!Y162 -> -0.1744236 | X9: - | Y9: - | Z9: =(résultats!AB13-résultats!AB161)/résultats!AB162 -> -1.2630715 | AA9: =(résultats!AC13-résultats!AC161)/résultats!AC162 -> -0.16435839 | AB9: =(résultats!AD13-résultats!AD161)/résultats!AD162 -> -0.14253398
C10: 0532E4 | D10: 139 | E10: =(résultats!E14-résultats!E161)/résultats!E162 -> 0.096279685 | F10: =(résultats!F14-résultats!F161)/résultats!F162 -> -0.37940956 | G10: =(résultats!G14-résultats!G161)/résultats!G162 -> -1.9300997 | H10: =(résultats!H14-résultats!H161)/résultats!H162 -> -0.85070664 | I10: =(résultats!I14-résultats!I161)/résultats!I162 -> -0.86752375 | J10: =(résultats!J14-résultats!J161)/résultats!J162 -> -0.84463602 | K10: =(résultats!K14-résultats!K161)/résultats!K162 -> 0.40849799 | L10: =(résultats!L14-résultats!L161)/résultats!L162 -> 0.44907395 | M10: =(résultats!O14-résultats!O161)/résultats!O162 -> -0.92461926 | N10: =(résultats!P14-résultats!P161)/résultats!P162 -> -0.80785134 | O10: =(résultats!Q14-résultats!Q161)/résultats!Q162 -> -0.87693533 | P10: =(résultats!R14-résultats!R161)/résultats!R162 -> -0.8399195 | Q10: =(résultats!S14-résultats!S161)/résultats!S162 -> 0.92164954 | R10: =(résultats!T14-résultats!T161)/résultats!T162 -> 0.94934145 | S10: =(résultats!U14-résultats!U161)/résultats!U162 -> -0.39160729 | T10: =(résultats!V14-résultats!V161)/résultats!V162 -> -0.69738965 | ... W10: =(résultats!Y14-résultats!Y161)/résultats!Y162 -> -0.84606193 | X10: - | Y10: - | Z10: - | AA10: - | AB10: -
C11: 0575E2 | D11: 139 | E11: - | F11: - | G11: - | H11: - | I11: - | J11: - | K11: - | L11: - | M11: - | N11: - | O11: - | P11: - | Q11: - | R11: - | S11: - | T11: - | U11: - | V11: - | W11: - | X11: - | Y11: - | Z11: - | AA11: - | AB11: - | AC11: - | AE11: - | AF11: - | AG11: - | AH11: -
C12: 0575E4 | D12: 139 | E12: =(résultats!E16-résultats!E161)/résultats!E162 -> 0.072601145 | F12: =(résultats!F16-résultats!F161)/résultats!F162 -> -0.18883422 | G12: =(résultats!G16-résultats!G161)/résultats!G162 -> -0.65498378 | H12: =(résultats!H16-résultats!H161)/résultats!H162 -> -0.56320032 | I12: =(résultats!I16-résultats!I161)/résultats!I162 -> -0.64236801 | J12: =(résultats!J16-résultats!J161)/résultats!J162 -> -0.56343797 | K12: =(résultats!K16-résultats!K161)/résultats!K162 -> 0.22709955 | L12: =(résultats!L16-résultats!L161)/résultats!L162 -> 0.30577076 | M12: =(résultats!O16-résultats!O161)/résultats!O162 -> -0.69250221 | N12: =(résultats!P16-résultats!P161)/résultats!P162 -> -0.57569056 | O12: =(résultats!Q16-résultats!Q161)/résultats!Q162 -> -0.64896312 | P12: =(résultats!R16-résultats!R161)/résultats!R162 -> -0.5560825 | Q12: =(résultats!S16-résultats!S161)/résultats!S162 -> 0.65149548 | R12: =(résultats!T16-résultats!T161)/résultats!T162 -> 1.0218863 | S12: =(résultats!U16-résultats!U161)/résultats!U162 -> -0.0023457565 | T12: =(résultats!V16-résultats!V161)/résultats!V162 -> -0.085627959 | ... W12: =(résultats!Y16-résultats!Y161)/résultats!Y162 -> -0.13600204 | X12: - | Y12: - | Z12: - | AA12: - | AB12: -
C13: 0639E1 | D13: 139 | E13: =(résultats!E17-résultats!E161)/résultats!E162 -> -0.25048631 | F13: =(résultats!F17-résultats!F161)/résultats!F162 -> -0.72547921 | G13: =(résultats!G17-résultats!G161)/résultats!G162 -> -1.1173806 | H13: =(résultats!H17-résultats!H161)/résultats!H162 -> -1.0571672 | I13: =(résultats!I17-résultats!I161)/résultats!I162 -> -1.1357537 | J13: =(résultats!J17-résultats!J161)/résultats!J162 -> -1.1565853 | K13: =(résultats!K17-résultats!K161)/résultats!K162 -> 0.50334251 | L13: =(résultats!L17-résultats!L161)/résultats!L162 -> 0.62040177 | M13: =(résultats!O17-résultats!O161)/résultats!O162 -> -1.0781879 | N13: =(résultats!P17-résultats!P161)/résultats!P162 -> -1.0120083 | O13: =(résultats!Q17-résultats!Q161)/résultats!Q162 -> -1.1439028 | P13: =(résultats!R17-résultats!R161)/résultats!R162 -> -1.1379966 | Q13: =(résultats!S17-résultats!S161)/résultats!S162 -> 0.98203692 | R13: =(résultats!T17-résultats!T161)/résultats!T162 -> 0.89493277 | S13: =(résultats!U17-résultats!U161)/résultats!U162 -> -0.39971691 | T13: =(résultats!V17-résultats!V161)/résultats!V162 -> -1.0013222 | ... W13: =(résultats!Y17-résultats!Y161)/résultats!Y162 -> -0.28377726 | X13: - | Y13: - | Z13: - | AA13: - | AB13: -
C14: 0639E4 | D14: 139 | E14: =(résultats!E18-résultats!E161)/résultats!E162 -> 0.45550807 | F14: =(résultats!F18-résultats!F161)/résultats!F162 -> 0.35520623 | G14: =(résultats!G18-résultats!G161)/résultats!G162 -> -0.65199925 | H14: =(résultats!H18-résultats!H161)/résultats!H162 -> -0.55557653 | I14: =(résultats!I18-résultats!I161)/résultats!I162 -> -0.5627425 | J14: =(résultats!J18-résultats!J161)/résultats!J162 -> -0.43347184 | K14: =(résultats!K18-résultats!K161)/résultats!K162 -> 0.41181423 | L14: =(résultats!L18-résultats!L161)/résultats!L162 -> 0.4474839 | M14: =(résultats!O18-résultats!O161)/résultats!O162 -> -0.69825872 | N14: =(résultats!P18-résultats!P161)/résultats!P162 -> -0.67402659 | O14: =(résultats!Q18-résultats!Q161)/résultats!Q162 -> -0.57808288 | P14: =(résultats!R18-résultats!R161)/résultats!R162 -> -0.43867618 | Q14: =(résultats!S18-résultats!S161)/résultats!S162 -> 0.65149548 | R14: =(résultats!T18-résultats!T161)/résultats!T162 -> 1.0400226 | S14: =(résultats!U18-résultats!U161)/résultats!U162 -> -0.63489576 | T14: =(résultats!V18-résultats!V161)/résultats!V162 -> -0.94677022 | ... W14: =(résultats!Y18-résultats!Y161)/résultats!Y162 -> -0.22466717 | X14: - | Y14: - | Z14: - | AA14: - | AB14: -
C15: 0699E2 | D15: 139 | E15: =(résultats!E19-résultats!E161)/résultats!E162 -> 0.36048235 | F15: =(résultats!F19-résultats!F161)/résultats!F162 -> -0.095348007 | G15: =(résultats!G19-résultats!G161)/résultats!G162 -> -0.84650846 | H15: =(résultats!H19-résultats!H161)/résultats!H162 -> -0.74665215 | I15: =(résultats!I19-résultats!I161)/résultats!I162 -> -0.76934145 | J15: =(résultats!J19-résultats!J161)/résultats!J162 -> -0.67994086 | K15: =(résultats!K19-résultats!K161)/résultats!K162 -> 0.14916786 | L15: =(résultats!L19-résultats!L161)/résultats!L162 -> 0.26621828 | M15: =(résultats!O19-résultats!O161)/résultats!O162 -> -1.0098526 | N15: =(résultats!P19-résultats!P161)/résultats!P162 -> -0.85830986 | O15: =(résultats!Q19-résultats!Q161)/résultats!Q162 -> -0.77005947 | P15: =(résultats!R19-résultats!R161)/résultats!R162 -> -0.67067047 | Q15: =(résultats!S19-résultats!S161)/résultats!S162 -> 1.2649041 | R15: =(résultats!T19-résultats!T161)/résultats!T162 -> 1.1352378 | S15: =(résultats!U19-résultats!U161)/résultats!U162 -> 0.28149078 | T15: =(résultats!V19-résultats!V161)/résultats!V162 -> -0.4596988 | ... W15: =(résultats!Y19-résultats!Y161)/résultats!Y162 -> -0.28747164 | X15: - | Y15: - | Z15: =(résultats!AB19-résultats!AB161)/résultats!AB162 -> -1.5564281 | AA15: =(résultats!AC19-résultats!AC161)/résultats!AC162 -> -0.16524352 | AB15: =(résultats!AD19-résultats!AD161)/résultats!AD162 -> -0.54826695
C16: 0699E3 | D16: 139 | E16: =(résultats!E20-résultats!E161)/résultats!E162 -> 0.5636193 | F16: =(résultats!F20-résultats!F161)/résultats!F162 -> 0.17354337 | G16: =(résultats!G20-résultats!G161)/résultats!G162 -> -0.7061325 | H16: =(résultats!H20-résultats!H161)/résultats!H162 -> -0.60200612 | I16: =(résultats!I20-résultats!I161)/résultats!I162 -> -0.59715692 | J16: =(résultats!J20-résultats!J161)/résultats!J162 -> -0.48411197 | K16: =(résultats!K20-résultats!K161)/résultats!K162 -> 0.058634449 | L16: =(résultats!L20-résultats!L161)/résultats!L162 -> 0.18433074 | M16: =(résultats!O20-résultats!O161)/résultats!O162 -> -0.91663443 | N16: =(résultats!P20-résultats!P161)/résultats!P162 -> -0.77946037 | O16: =(résultats!Q20-résultats!Q161)/résultats!Q162 -> -0.59752495 | P16: =(résultats!R20-résultats!R161)/résultats!R162 -> -0.48295386 | Q16: =(résultats!S20-résultats!S161)/résultats!S162 -> 1.1790905 | R16: =(résultats!T20-résultats!T161)/résultats!T162 -> 1.1171015 | S16: =(résultats!U20-résultats!U161)/résultats!U162 -> 0.3950254 | T16: =(résultats!V20-résultats!V161)/résultats!V162 -> 0.023476037 | ... W16: =(résultats!Y20-résultats!Y161)/résultats!Y162 -> -0.26604423 | X16: - | Y16: - | Z16: - | AA16: - | AB16: -
B17: 2 | C17: 0025E2 | D17: 11389 | E17: =(résultats!E21-résultats!E161)/résultats!E162 -> -0.047037797 | F17: =(résultats!F21-résultats!F161)/résultats!F162 -> -0.30393793 | G17: =(résultats!G21-résultats!G161)/résultats!G162 -> -0.5661682 | H17: =(résultats!H21-résultats!H161)/résultats!H162 -> -0.56340637 | I17: =(résultats!I21-résultats!I161)/résultats!I162 -> -0.58264888 | J17: =(résultats!J21-résultats!J161)/résultats!J162 -> -0.60145631 | K17: =(résultats!K21-résultats!K161)/résultats!K162 -> 0.19393713 | L17: =(résultats!L21-résultats!L161)/résultats!L162 -> 0.28688892 | M17: =(résultats!O21-résultats!O161)/résultats!O162 -> -0.57402967 | N17: =(résultats!P21-résultats!P161)/résultats!P162 -> -0.5954352 | O17: =(résultats!Q21-résultats!Q161)/résultats!Q162 -> -0.58808166 | P17: =(résultats!R21-résultats!R161)/résultats!R162 -> -0.59546516 | Q17: =(résultats!S21-résultats!S161)/résultats!S162 -> 0.47033335 | R17: =(résultats!T21-résultats!T161)/résultats!T162 -> 0.3735163 | S17: =(résultats!U21-résultats!U161)/résultats!U162 -> -0.22130537 | T17: =(résultats!V21-résultats!V161)/résultats!V162 -> -0.69738965 | ... Y17: =(résultats!AA21-résultats!AA161)/résultats!AA162 -> -1.1855083 | Z17: - | AA17: - | AB17: - | AD17: =0.865*N17+0.814*P17-0.789*R17 -> -1.2944645
C18: 0025E4 | D18: 11389 | E18: =(résultats!E22-résultats!E161)/résultats!E162 -> 0.089425371 | F18: =(résultats!F22-résultats!F161)/résultats!F162 -> -0.14047928 | G18: =(résultats!G22-résultats!G161)/résultats!G162 -> -0.54033655 | H18: =(résultats!H22-résultats!H161)/résultats!H162 -> -0.49589115 | I18: =(résultats!I22-résultats!I161)/résultats!I162 -> -0.53383889 | J18: =(résultats!J22-résultats!J161)/résultats!J162 -> -0.48916068 | K18: =(résultats!K22-résultats!K161)/résultats!K162 -> 0.27352694 | L18: =(résultats!L22-résultats!L161)/résultats!L162 -> 0.24594515 | M18: =(résultats!O22-résultats!O161)/résultats!O162 -> -0.5411619 | N18: =(résultats!P22-résultats!P161)/résultats!P162 -> -0.5269097 | O18: =(résultats!Q22-résultats!Q161)/résultats!Q162 -> -0.54430922 | P18: =(résultats!R22-résultats!R161)/résultats!R162 -> -0.4828797 | Q18: =(résultats!S22-résultats!S161)/résultats!S162 -> 0.39087628 | R18: =(résultats!T22-résultats!T161)/résultats!T162 -> 1.1715102 | S18: =(résultats!U22-résultats!U161)/résultats!U162 -> -0.46459383 | T18: =(résultats!V22-résultats!V161)/résultats!V162 -> -0.47528509 | ... Y18: =(résultats!AA22-résultats!AA161)/résultats!AA162 -> -1.0470111 | Z18: - | AA18: - | AB18: - | AD18: =0.865*N18+0.814*P18-0.789*R18 -> -1.7731625
C19: 0244E1 | D19: 11389 | E19: =(résultats!E23-résultats!E161)/résultats!E162 -> 0.0099776364 | F19: =(résultats!F23-résultats!F161)/résultats!F162 -> -0.37466888 | G19: =(résultats!G23-résultats!G161)/résultats!G162 -> -0.95096711 | H19: =(résultats!H23-résultats!H161)/résultats!H162 -> -0.93079081 | I19: =(résultats!I23-résultats!I161)/résultats!I162 -> -0.92949219 | J19: =(résultats!J23-résultats!J161)/résultats!J162 -> -0.93513039 | K19: =(résultats!K23-résultats!K161)/résultats!K162 -> 0.39622789 | L19: =(résultats!L23-résultats!L161)/résultats!L162 -> 0.59456347 | M19: =(résultats!O23-résultats!O161)/résultats!O162 -> -0.97159975 | N19: =(résultats!P23-résultats!P161)/résultats!P162 -> -0.87818354 | O19: =(résultats!Q23-résultats!Q161)/résultats!Q162 -> -0.93681692 | P19: =(résultats!R23-résultats!R161)/résultats!R162 -> -0.93136737 | Q19: =(résultats!S23-résultats!S161)/résultats!S162 -> 1.0074632 | R19: =(résultats!T23-résultats!T161)/résultats!T162 -> 0.81331976 | S19: =(résultats!U23-résultats!U161)/résultats!U162 -> -0.2375246 | T19: =(résultats!V23-résultats!V161)/résultats!V162 -> -0.6233548 | ... Y19: =(résultats!AA23-résultats!AA161)/résultats!AA162 -> -1.3904843 | Z19: - | AA19: - | AB19: - | AD19: =0.865*N19+0.814*P19-0.789*R19 -> -2.1594711
C20: 0374E3 | D20: 11389 | E20: =(résultats!E24-résultats!E161)/résultats!E162 -> -0.070716337 | F20: =(résultats!F24-résultats!F161)/résultats!F162 -> -0.19319564 | G20: =(résultats!G24-résultats!G161)/résultats!G162 -> -0.93285409 | H20: =(résultats!H24-résultats!H161)/résultats!H162 -> -0.77227085 | I20: =(résultats!I24-résultats!I161)/résultats!I162 -> -0.93455314 | J20: =(résultats!J24-résultats!J161)/résultats!J162 -> -0.78466343 | K20: =(résultats!K24-résultats!K161)/résultats!K162 -> 0.024145531 | L20: =(résultats!L24-résultats!L161)/résultats!L162 -> -0.41253403 | M20: =(résultats!O24-résultats!O161)/résultats!O162 -> -1.07206 | N20: =(résultats!P24-résultats!P161)/résultats!P162 -> -0.56717327 | O20: =(résultats!Q24-résultats!Q161)/résultats!Q162 -> -0.9241518 | P20: =(résultats!R24-résultats!R161)/résultats!R162 -> -0.74016492 | Q20: =(résultats!S24-résultats!S161)/résultats!S162 -> 1.3189349 | R20: =(résultats!T24-résultats!T161)/résultats!T162 -> 2.1599345 | S20: =(résultats!U24-résultats!U161)/résultats!U162 -> 0.80861578 | T20: =(résultats!V24-résultats!V161)/résultats!V162 -> 1.8704508 | ... AB20: =(résultats!AD24-résultats!AD161)/résultats!AD162 -> 1.0324536 | AD20: =0.865*N20+0.814*P20-0.789*R20 -> -2.7972874
C21: 0429E2 | D21: 11389 | E21: =(résultats!E25-résultats!E161)/résultats!E162 -> -0.16761142 | F21: =(résultats!F25-résultats!F161)/résultats!F162 -> -0.26658137 | G21: =(résultats!G25-résultats!G161)/résultats!G162 -> -0.57471013 | H21: =(résultats!H25-résultats!H161)/résultats!H162 -> -0.58717063 | I21: =(résultats!I25-résultats!I161)/résultats!I162 -> -0.60424224 | J21: =(résultats!J25-résultats!J161)/résultats!J162 -> -0.62907125 | K21: =(résultats!K25-résultats!K161)/résultats!K162 -> 0.19161576 | L21: =(résultats!L25-résultats!L161)/résultats!L162 -> 0.40654013 | M21: =(résultats!O25-résultats!O161)/résultats!O162 -> -0.56047404 | N21: =(résultats!P25-résultats!P161)/résultats!P162 -> -0.59891955 | O21: =(résultats!Q25-résultats!Q161)/résultats!Q162 -> -0.60974568 | P21: =(résultats!R25-résultats!R161)/résultats!R162 -> -0.62431611 | Q21: =(résultats!S25-résultats!S161)/résultats!S162 -> 0.30824092 | R21: =(résultats!T25-résultats!T161)/résultats!T162 -> 0.50500393 | S21: =(résultats!U25-résultats!U161)/résultats!U162 -> -0.11588037 | T21: =(résultats!V25-résultats!V161)/résultats!V162 -> -0.038869104 | ... X21: =(résultats!Z25-résultats!Z161)/résultats!Z162 -> -0.19413699 | Y21: - | Z21: - | AA21: - | AB21: - | AC21: - | AD21: =0.865*N21+0.814*P21-0.789*R21 -> -1.4247068 | AE21: - | AF21: - | AG21: - | AH21: -
C22: 0429E4 | D22: 11389 | E22: =(résultats!E26-résultats!E161)/résultats!E162 -> 0.11902355 | F22: =(résultats!F26-résultats!F161)/résultats!F162 -> -0.18257652 | G22: =(résultats!G26-résultats!G161)/résultats!G162 -> -0.40644423 | H22: =(résultats!H26-résultats!H161)/résultats!H162 -> -0.45104126 | I22: =(résultats!I26-résultats!I161)/résultats!I162 -> -0.40135464 | J22: =(résultats!J26-résultats!J161)/résultats!J162 -> -0.46996027 | K22: =(résultats!K26-résultats!K161)/résultats!K162 -> 0.071567793 | L22: =(résultats!L26-résultats!L161)/résultats!L162 -> 0.23958495 | M22: =(résultats!O26-résultats!O161)/résultats!O162 -> -0.46187072 | N22: =(résultats!P26-résultats!P161)/résultats!P162 -> -0.44418871 | O22: =(résultats!Q26-résultats!Q161)/résultats!Q162 -> -0.40577055 | P22: =(résultats!R26-résultats!R161)/résultats!R162 -> -0.47294132 | Q22: =(résultats!S26-résultats!S161)/résultats!S162 -> 0.41630254 | R22: =(résultats!T26-résultats!T161)/résultats!T162 -> 0.22389245 | S22: =(résultats!U26-résultats!U161)/résultats!U162 -> 0.046311936 | T22: =(résultats!V26-résultats!V161)/résultats!V162 -> -0.24928395 | ... AB22: =(résultats!AD26-résultats!AD161)/résultats!AD162 -> -0.70262188 | AD22: =0.865*N22+0.814*P22-0.789*R22 -> -0.94584861
C23: 0532E1 | D23: 11389 | E23: =(résultats!E27-résultats!E161)/résultats!E162 -> 0.10188776 | F23: =(résultats!F27-résultats!F161)/résultats!F162 -> -0.22694929 | G23: =(résultats!G27-résultats!G161)/résultats!G162 -> -0.55320091 | H23: =(résultats!H27-résultats!H161)/résultats!H162 -> -0.48613819 | I23: =(résultats!I27-résultats!I161)/résultats!I162 -> -0.54609762 | J23: =(résultats!J27-résultats!J161)/résultats!J162 -> -0.51968245 | K23: =(résultats!K27-résultats!K161)/résultats!K162 -> 0.38661079 | L23: =(résultats!L27-résultats!L161)/résultats!L162 -> 0.49061399 | M23: =(résultats!O27-résultats!O161)/résultats!O162 -> -0.51702173 | N23: =(résultats!P27-résultats!P161)/résultats!P162 -> -0.3919235 | O23: =(résultats!Q27-résultats!Q161)/résultats!Q162 -> -0.55986288 | P23: =(résultats!R27-résultats!R161)/résultats!R162 -> -0.53064323 | Q23: =(résultats!S27-résultats!S161)/résultats!S162 -> 0.36545001 | R23: =(résultats!T27-résultats!T161)/résultats!T162 -> 0.047064253 | S23: =(résultats!U27-résultats!U161)/résultats!U162 -> -0.71599191 | T23: =(résultats!V27-résultats!V161)/résultats!V162 -> -0.86883879 | ... Y23: =(résultats!AA27-résultats!AA161)/résultats!AA162 -> -0.9334433 | Z23: - | AA23: - | AB23: - | AD23: =0.865*N23+0.814*P23-0.789*R23 -> -0.80809111
C24: 0532E4 | D24: 11389 | E24: =(résultats!E28-résultats!E161)/résultats!E162 -> -0.052957432 | F24: =(résultats!F28-résultats!F161)/résultats!F162 -> -0.37372074 | G24: =(résultats!G28-résultats!G161)/résultats!G162 -> -0.58057629 | H24: =(résultats!H28-résultats!H161)/résultats!H162 -> -0.62336648 | I24: =(résultats!I28-résultats!I161)/résultats!I162 -> -0.59220844 | J24: =(résultats!J28-résultats!J161)/résultats!J162 -> -0.67144984 | K24: =(résultats!K28-résultats!K161)/résultats!K162 -> 0.52987245 | L24: =(résultats!L28-résultats!L161)/résultats!L162 -> 0.66710947 | M24: =(résultats!O28-résultats!O161)/résultats!O162 -> -0.46502751 | N24: =(résultats!P28-résultats!P161)/résultats!P162 -> -0.4565775 | O24: =(résultats!Q28-résultats!Q161)/résultats!Q162 -> -0.61030117 | P24: =(résultats!R28-résultats!R161)/résultats!R162 -> -0.67882884 | Q24: =(résultats!S28-résultats!S161)/résultats!S162 -> 0.19382273 | R24: =(résultats!T28-résultats!T161)/résultats!T162 -> 0.01532586 | S24: =(résultats!U28-résultats!U161)/résultats!U162 -> -1.0079381 | T24: =(résultats!V28-résultats!V161)/résultats!V162 -> -0.67401023 | ... Y24: =(résultats!AA28-résultats!AA161)/résultats!AA162 -> -0.62782597 | Z24: - | AA24: - | AB24: - | AD24: =0.865*N24+0.814*P24-0.789*R24 -> -0.95959831
C25: 0575E2 | D25: 11389 | E25: =(résultats!E29-résultats!E161)/résultats!E162 -> 0.35830143 | F25: =(résultats!F29-résultats!F161)/résultats!F162 -> 0.13410091 | G25: =(résultats!G29-résultats!G161)/résultats!G162 -> -0.5007143 | H25: =(résultats!H29-résultats!H161)/résultats!H162 -> -0.48558873 | I25: =(résultats!I29-résultats!I161)/résultats!I162 -> -0.44105493 | J25: =(résultats!J29-résultats!J161)/résultats!J162 -> -0.39683042 | K25: =(résultats!K29-résultats!K161)/résultats!K162 -> 0.33620391 | L25: =(résultats!L29-résultats!L161)/résultats!L162 -> 0.50631573 | M25: =(résultats!O29-résultats!O161)/résultats!O162 -> -0.52519225 | N25: =(résultats!P29-résultats!P161)/résultats!P162 -> -0.39669834 | O25: =(résultats!Q29-résultats!Q161)/résultats!Q162 -> -0.4538758 | P25: =(résultats!R29-résultats!R161)/résultats!R162 -> -0.41553609 | Q25: =(résultats!S29-résultats!S161)/résultats!S162 -> 0.54025558 | R25: =(résultats!T29-résultats!T161)/résultats!T162 -> 0.31003952 | S25: =(résultats!U29-résultats!U161)/résultats!U162 -> -0.39971691 | T25: =(résultats!V29-résultats!V161)/résultats!V162 -> -0.35059481 | ... Y25: =(résultats!AA29-résultats!AA161)/résultats!AA162 -> -0.79633099 | Z25: - | AA25: - | AB25: - | AD25: =0.865*N25+0.814*P25-0.789*R25 -> -0.92601162
C26: 0575E4 | D26: 11389 | E26: =(résultats!E30-résultats!E161)/résultats!E162 -> 0.098149044 | F26: =(résultats!F30-résultats!F161)/résultats!F162 -> -0.1677856 | G26: =(résultats!G30-résultats!G161)/résultats!G162 -> -0.39851978 | H26: =(résultats!H30-résultats!H161)/résultats!H162 -> -0.45275833 | I26: =(résultats!I30-résultats!I161)/résultats!I162 -> -0.39460672 | J26: =(résultats!J30-résultats!J161)/résultats!J162 -> -0.49665726 | K26: =(résultats!K30-résultats!K161)/résultats!K162 -> 0.27286369 | L26: =(résultats!L30-résultats!L161)/résultats!L162 -> 0.39978242 | M26: =(résultats!O30-résultats!O161)/résultats!O162 -> -0.37329485 | N26: =(résultats!P30-résultats!P161)/résultats!P162 -> -0.34753033 | O26: =(résultats!Q30-résultats!Q161)/résultats!Q162 -> -0.40721482 | P26: =(résultats!R30-résultats!R161)/résultats!R162 -> -0.50498146 | Q26: =(résultats!S30-résultats!S161)/résultats!S162 -> 0.25103182 | R26: =(résultats!T30-résultats!T161)/résultats!T162 -> 0.10600698 | S26: =(résultats!U30-résultats!U161)/résultats!U162 -> -0.40782653 | T26: =(résultats!V30-résultats!V161)/résultats!V162 -> -0.52594052 | ... Y26: =(résultats!AA30-résultats!AA161)/résultats!AA162 -> -0.85496151 | Z26: - | AA26: - | AB26: - | AD26: =0.865*N26+0.814*P26-0.789*R26 -> -0.79530815
C27: 0639E1 | D27: 11389 | E27: =(résultats!E31-résultats!E161)/résultats!E162 -> -0.29285843 | F27: =(résultats!F31-résultats!F161)/résultats!F162 -> -0.65190385 | G27: =(résultats!G31-résultats!G161)/résultats!G162 -> -0.80791536 | H27: =(résultats!H31-résultats!H161)/résultats!H162 -> -0.86011618 | I27: =(résultats!I31-résultats!I161)/résultats!I162 -> -0.85245339 | J27: =(résultats!J31-résultats!J161)/résultats!J162 -> -0.93750176 | K27: =(résultats!K31-résultats!K161)/résultats!K162 -> 0.51329124 | L27: =(résultats!L31-résultats!L161)/résultats!L162 -> 0.69155648 | M27: =(résultats!O31-résultats!O161)/résultats!O162 -> -0.69491623 | N27: =(résultats!P31-résultats!P161)/résultats!P162 -> -0.7306795 | O27: =(résultats!Q31-résultats!Q161)/résultats!Q162 -> -0.86593667 | P27: =(résultats!R31-résultats!R161)/résultats!R162 -> -0.93574323 | Q27: =(résultats!S31-résultats!S161)/résultats!S162 -> 0.40358941 | R27: =(résultats!T31-résultats!T161)/résultats!T162 -> 0.3327098 | S27: =(résultats!U31-résultats!U161)/résultats!U162 -> -0.70788229 | T27: =(résultats!V31-résultats!V161)/résultats!V162 -> -0.81818336 | ... Y27: =(résultats!AA31-résultats!AA161)/résultats!AA162 -> -1.2819948 | Z27: - | AA27: - | AB27: - | AD27: =0.865*N27+0.814*P27-0.789*R27 -> -1.6562408
C28: 0639E4 | D28: 11389 | E28: =(résultats!E32-résultats!E161)/résultats!E162 -> 0.37761813 | F28: =(résultats!F32-résultats!F161)/résultats!F162 -> 0.17069896 | G28: =(résultats!G32-résultats!G161)/résultats!G162 -> -0.31063043 | H28: =(résultats!H32-résultats!H161)/résultats!H162 -> -0.32439013 | I28: =(résultats!I32-résultats!I161)/résultats!I162 -> -0.25762386 | J28: =(résultats!J32-résultats!J161)/résultats!J162 -> -0.27642624 | K28: =(résultats!K32-résultats!K161)/résultats!K162 -> 0.17901404 | L28: =(résultats!L32-résultats!L161)/résultats!L162 -> 0.38109934 | M28: =(résultats!O32-résultats!O161)/résultats!O162 -> -0.35973922 | N28: =(résultats!P32-résultats!P161)/résultats!P162 -> -0.37204981 | O28: =(résultats!Q32-résultats!Q161)/résultats!Q162 -> -0.26889835 | P28: =(résultats!R32-résultats!R161)/résultats!R162 -> -0.29078724 | Q28: =(résultats!S32-résultats!S161)/résultats!S162 -> 0.32731062 | R28: =(résultats!T32-résultats!T161)/résultats!T162 -> 0.1558816 | S28: =(résultats!U32-résultats!U161)/résultats!U162 -> -0.31051114 | T28: =(résultats!V32-résultats!V161)/résultats!V162 -> -0.26876681 | ... Y28: =(résultats!AA32-résultats!AA161)/résultats!AA162 -> -0.79817762 | Z28: - | AA28: - | AB28: - | AD28: =0.865*N28+0.814*P28-0.789*R28 -> -0.68151449
C29: 0699E2 | D29: 11389 | E29: =(résultats!E33-résultats!E161)/résultats!E162 -> 0.35425115 | F29: =(résultats!F33-résultats!F161)/résultats!F162 -> 0.021651979 | G29: =(résultats!G33-résultats!G161)/résultats!G162 -> -0.54013072 | H29: =(résultats!H33-résultats!H161)/résultats!H162 -> -0.53297988 | I29: =(résultats!I33-résultats!I161)/résultats!I162 -> -0.48457905 | J29: =(résultats!J33-résultats!J161)/résultats!J162 -> -0.50254742 | K29: =(résultats!K33-résultats!K161)/résultats!K162 -> 0.14120888 | L29: =(résultats!L33-résultats!L161)/résultats!L162 -> 0.27873992 | M29: =(résultats!O33-résultats!O161)/résultats!O162 -> -0.64422187 | N29: =(résultats!P33-résultats!P161)/résultats!P162 -> -0.59401565 | O29: =(résultats!Q33-résultats!Q161)/résultats!Q162 -> -0.4904269 | P29: =(résultats!R33-résultats!R161)/résultats!R162 -> -0.50008644 | Q29: =(résultats!S33-résultats!S161)/résultats!S162 -> 0.72459599 | R29: =(résultats!T33-résultats!T161)/résultats!T162 -> 0.58661695 | S29: =(résultats!U33-résultats!U161)/résultats!U162 -> -0.010455372 | T29: =(résultats!V33-résultats!V161)/résultats!V162 -> -0.37397424 | ... Y29: =(résultats!AA33-résultats!AA161)/résultats!AA162 -> -1.2367523 | Z29: - | AA29: - | AB29: - | AD29: =0.865*N29+0.814*P29-0.789*R29 -> -1.3837347
C30: 0699E3 | D30: 11389 | E30: =(résultats!E34-résultats!E161)/résultats!E162 -> 0.58979032 | F30: =(résultats!F34-résultats!F161)/résultats!F162 -> 0.31538452 | G30: =(résultats!G34-résultats!G161)/résultats!G162 -> -0.46273869 | H30: =(résultats!H34-résultats!H161)/résultats!H162 -> -0.41257888 | I30: =(résultats!I34-résultats!I161)/résultats!I162 -> -0.36559065 | J30: =(résultats!J34-résultats!J161)/résultats!J162 -> -0.3125322 | K30: =(résultats!K34-résultats!K161)/résultats!K162 -> 0.11103107 | L30: =(résultats!L34-résultats!L161)/résultats!L162 -> 0.21652924 | M30: =(résultats!O34-résultats!O161)/résultats!O162 -> -0.61061132 | N30: =(résultats!P34-résultats!P161)/résultats!P162 -> -0.53491079 | O30: =(résultats!Q34-résultats!Q161)/résultats!Q162 -> -0.37244128 | P30: =(résultats!R34-résultats!R161)/résultats!R162 -> -0.31615235 | Q30: =(résultats!S34-résultats!S161)/résultats!S162 -> 0.75320054 | R30: =(résultats!T34-résultats!T161)/résultats!T162 -> 0.67276402 | S30: =(résultats!U34-résultats!U161)/résultats!U162 -> -0.051003449 | T30: =(résultats!V34-résultats!V161)/résultats!V162 -> -0.33111195 | ... Y30: =(résultats!AA34-résultats!AA161)/résultats!AA162 -> -1.3101559 | Z30: - | AA30: - | AB30: - | AD30: =0.865*N30+0.814*P30-0.789*R30 -> -1.2508567
B31: 3 | C31: 0025E2 | D31: =D17+11111+139 -> 22639 | E31: =(résultats!E35-résultats!E161)/résultats!E162 -> -0.15577215 | F31: =(résultats!F35-résultats!F161)/résultats!F162 -> -0.53528312 | G31: =(résultats!G35-résultats!G161)/résultats!G162 -> -0.84321518 | H31: =(résultats!H35-résultats!H161)/résultats!H162 -> -0.83071993 | I31: =(résultats!I35-résultats!I161)/résultats!I162 -> -0.86010104 | J31: =(résultats!J35-résultats!J161)/résultats!J162 -> -0.88341933 | K31: =(résultats!K35-résultats!K161)/résultats!K162 -> 0.86448128 | L31: =(résultats!L35-résultats!L161)/résultats!L162 -> 0.80464874 | M31: =(résultats!O35-résultats!O161)/résultats!O162 -> -0.63438011 | N31: =(résultats!P35-résultats!P161)/résultats!P162 -> -0.65518531 | O31: =(résultats!Q35-résultats!Q161)/résultats!Q162 -> -0.88482326 | P31: =(résultats!R35-résultats!R161)/résultats!R162 -> -0.88523552 | Q31: =(résultats!S35-résultats!S161)/résultats!S162 -> 0.19700101 | R31: =(résultats!T35-résultats!T161)/résultats!T162 -> 0.77704731 | S31: =(résultats!U35-résultats!U161)/résultats!U162 -> -1.9405438 | T31: =(résultats!V35-résultats!V161)/résultats!V162 -> -1.3013582 | ... Y31: =(résultats!AA35-résultats!AA161)/résultats!AA162 -> -1.0599375 | Z31: - | AA31: - | AB31: - | AD31: =0.865*N31+0.814*P31-0.789*R31 -> -1.9004073
C32: 0025E4 | D32: =D18+11111+139 -> 22639 | E32: =(résultats!E36-résultats!E161)/résultats!E162 -> -0.059811746 | F32: =(résultats!F36-résultats!F161)/résultats!F162 -> -0.38225397 | G32: =(résultats!G36-résultats!G161)/résultats!G162 -> -0.45224137 | H32: =(résultats!H36-résultats!H161)/résultats!H162 -> -0.45632984 | I32: =(résultats!I36-résultats!I161)/résultats!I162 -> -0.47996796 | J32: =(résultats!J36-résultats!J161)/résultats!J162 -> -0.51241536 | K32: =(résultats!K36-résultats!K161)/résultats!K162 -> 0.26523633 | L32: =(résultats!L36-résultats!L161)/résultats!L162 -> 0.42522321 | M32: =(résultats!O36-résultats!O161)/résultats!O162 -> -0.40820526 | N32: =(résultats!P36-résultats!P161)/résultats!P162 -> -0.33527059 | O32: =(résultats!Q36-résultats!Q161)/résultats!Q162 -> -0.48998251 | P32: =(résultats!R36-résultats!R161)/résultats!R162 -> -0.52315236 | Q32: =(résultats!S36-résultats!S161)/résultats!S162 -> 0.26056667 | R32: =(résultats!T36-résultats!T161)/résultats!T162 -> -0.030014703 | S32: =(résultats!U36-résultats!U161)/résultats!U162 -> -0.40782653 | T32: =(résultats!V36-résultats!V161)/résultats!V162 -> -0.68959651 | ... AB32: =(résultats!AD36-résultats!AD161)/résultats!AD162 -> -1.7201044 | AD32: =0.865*N32+0.814*P32-0.789*R32 -> -0.69217348
C33: 0244E1 | D33: =D19+11111+139 -> 22639 | E33: =(résultats!E37-résultats!E161)/résultats!E162 -> -0.00061539487 | F33: =(résultats!F37-résultats!F161)/résultats!F162 -> -0.39856191 | G33: =(résultats!G37-résultats!G161)/résultats!G162 -> -0.97968038 | H33: =(résultats!H37-résultats!H161)/résultats!H162 -> -0.97550333 | I33: =(résultats!I37-résultats!I161)/résultats!I162 -> -0.95535924 | J33: =(résultats!J37-résultats!J161)/résultats!J162 -> -0.98538804 | K33: =(résultats!K37-résultats!K161)/résultats!K162 -> 0.43336981 | L33: =(résultats!L37-résultats!L161)/résultats!L162 -> 0.63073709 | M33: =(résultats!O37-résultats!O161)/résultats!O162 -> -0.99016911 | N33: =(résultats!P37-résultats!P161)/résultats!P162 -> -0.95883973 | O33: =(résultats!Q37-résultats!Q161)/résultats!Q162 -> -0.96403582 | P33: =(résultats!R37-résultats!R161)/résultats!R162 -> -0.97653506 | Q33: =(résultats!S37-résultats!S161)/résultats!S162 -> 0.95661065 | R33: =(résultats!T37-résultats!T161)/résultats!T162 -> 0.92667117 | S33: =(résultats!U37-résultats!U161)/résultats!U162 -> -0.36727845 | T33: =(résultats!V37-résultats!V161)/résultats!V162 -> -0.59218223 | ... AB33: =(résultats!AD37-résultats!AD161)/résultats!AD162 -> -0.42730308 | AD33: =0.865*N33+0.814*P33-0.789*R33 -> -2.3554395
C34: 0374E3 | D34: =D20+11111+139 -> 22639 | E34: =(résultats!E38-résultats!E161)/résultats!E162 -> -0.1352092 | F34: =(résultats!F38-résultats!F161)/résultats!F162 -> -0.23737878 | G34: =(résultats!G38-résultats!G161)/résultats!G162 -> -0.89714261 | H34: =(résultats!H38-résultats!H161)/résultats!H162 -> -0.74651479 | I34: =(résultats!I38-résultats!I161)/résultats!I162 -> -0.91003568 | J34: =(résultats!J38-résultats!J161)/résultats!J162 -> -0.71413442 | K34: =(résultats!K38-résultats!K161)/résultats!K162 -> 0.13126015 | L34: =(résultats!L38-résultats!L161)/résultats!L162 -> -0.32388878 | M34: =(résultats!O38-résultats!O161)/résultats!O162 -> -0.9760564 | N34: =(résultats!P38-résultats!P161)/résultats!P162 -> -0.47670929 | O34: =(résultats!Q38-résultats!Q161)/résultats!Q162 -> -0.90482082 | P34: =(résultats!R38-résultats!R161)/résultats!R162 -> -0.7020431 | Q34: =(résultats!S38-résultats!S161)/résultats!S162 -> 1.016998 | R34: =(résultats!T38-résultats!T161)/résultats!T162 -> 2.0465831 | S34: =(résultats!U38-résultats!U161)/résultats!U162 -> 0.31392924 | T34: =(résultats!V38-résultats!V161)/résultats!V162 -> 0.62744459 | ... AB34: =(résultats!AD38-résultats!AD161)/résultats!AD162 -> 0.060962525 | AD34: =0.865*N34+0.814*P34-0.789*R34 -> -2.5985706
C35: 0429E2 | D35: =D21+11111+139 -> 22639 | E35: =(résultats!E39-résultats!E161)/résultats!E162 -> -0.25640594 | F35: =(résultats!F39-résultats!F161)/résultats!F162 -> -0.30393793 | G35: =(résultats!G39-résultats!G161)/résultats!G162 -> -0.60908372 | H35: =(résultats!H39-résultats!H161)/résultats!H162 -> -0.57755503 | I35: =(résultats!I39-résultats!I161)/résultats!I162 -> -0.65653865 | J35: =(résultats!J39-résultats!J161)/résultats!J162 -> -0.60535759 | K35: =(résultats!K39-résultats!K161)/résultats!K162 -> 0.18929439 | L35: =(résultats!L39-résultats!L161)/résultats!L162 -> 0.33836677 | M35: =(résultats!O39-résultats!O161)/résultats!O162 -> -0.58442852 | N35: =(résultats!P39-résultats!P161)/résultats!P162 -> -0.59478995 | O35: =(résultats!Q39-résultats!Q161)/résultats!Q162 -> -0.66085056 | P35: =(résultats!R39-résultats!R161)/résultats!R162 -> -0.60332686 | Q35: =(résultats!S39-résultats!S161)/résultats!S162 -> 0.19382273 | R35: =(résultats!T39-résultats!T161)/résultats!T162 -> 0.48686771 | S35: =(résultats!U39-résultats!U161)/résultats!U162 -> -0.37538806 | T35: =(résultats!V39-résultats!V161)/résultats!V162 -> -0.57269937 | ... Y35: =(résultats!AA39-résultats!AA161)/résultats!AA162 -> -0.39930547 | Z35: - | AA35: - | AB35: - | AD35: =0.865*N35+0.814*P35-0.789*R35 -> -1.38974
C36: 0429E4 | D36: =D22+11111+139 -> 22639 | E36: =(résultats!E40-résultats!E161)/résultats!E162 -> 0.097214365 | F36: =(résultats!F40-résultats!F161)/résultats!F162 -> -0.13744525 | G36: =(résultats!G40-résultats!G161)/résultats!G162 -> -0.34747397 | H36: =(résultats!H40-résultats!H161)/résultats!H162 -> -0.39403452 | I36: =(résultats!I40-résultats!I161)/résultats!I162 -> -0.34669646 | J36: =(résultats!J40-résultats!J161)/résultats!J162 -> -0.43974448 | K36: =(résultats!K40-résultats!K161)/résultats!K162 -> 0.052333589 | L36: =(résultats!L40-résultats!L161)/résultats!L162 -> 0.20957277 | M36: =(résultats!O40-résultats!O161)/résultats!O162 -> -0.39372115 | N36: =(résultats!P40-résultats!P161)/résultats!P162 -> -0.43025132 | O36: =(résultats!Q40-résultats!Q161)/résultats!Q162 -> -0.35166603 | P36: =(résultats!R40-résultats!R161)/résultats!R162 -> -0.42836697 | Q36: =(résultats!S40-résultats!S161)/résultats!S162 -> 0.32413233 | R36: =(résultats!T40-résultats!T161)/résultats!T162 -> 0.2284265 | S36: =(résultats!U40-résultats!U161)/résultats!U162 -> 0.054421551 | T36: =(résultats!V40-résultats!V161)/résultats!V162 -> 0.12868346 | ... Y36: =(résultats!AA40-résultats!AA161)/résultats!AA162 -> -0.38314745 | Z36: - | AA36: - | AB36: - | AD36: =0.865*N36+0.814*P36-0.789*R36 -> -0.90108662
C37: 0532E1 | D37: =D23+11111+139 -> 22639 | E37: =(résultats!E41-résultats!E161)/résultats!E162 -> 0.43868384 | F37: =(résultats!F41-résultats!F161)/résultats!F162 -> 0.23896476 | G37: =(résultats!G41-résultats!G161)/résultats!G162 -> -0.36651323 | H37: =(résultats!H41-résultats!H161)/résultats!H162 -> -0.3765204 | I37: =(résultats!I41-résultats!I161)/résultats!I162 -> -0.30036071 | J37: =(résultats!J41-résultats!J161)/résultats!J162 -> -0.30289374 | K37: =(résultats!K41-résultats!K161)/résultats!K162 -> 0.29674063 | L37: =(résultats!L41-résultats!L161)/résultats!L162 -> 0.3958073 | M37: =(résultats!O41-résultats!O161)/résultats!O162 -> -0.3953924 | N37: =(résultats!P41-résultats!P161)/résultats!P162 -> -0.43541332 | O37: =(résultats!Q41-résultats!Q161)/résultats!Q162 -> -0.31600372 | P37: =(résultats!R41-résultats!R161)/résultats!R162 -> -0.30932898 | Q37: =(résultats!S41-résultats!S161)/résultats!S162 -> 0.22560556 | R37: =(résultats!T41-résultats!T161)/résultats!T162 -> 0.65916185 | S37: =(résultats!U41-résultats!U161)/résultats!U162 -> -0.83763614 | T37: =(résultats!V41-résultats!V161)/résultats!V162 -> -1.0909434 | ... AB37: =(résultats!AD41-résultats!AD161)/résultats!AD162 -> -1.4542359 | AD37: =0.865*N37+0.814*P37-0.789*R37 -> -1.148505
C38: 0532E4 | D38: =D24+11111+139 -> 22639 | E38: =(résultats!E42-résultats!E161)/résultats!E162 -> -0.11495782 | F38: =(résultats!F42-résultats!F161)/résultats!F162 -> -0.26866727 | G38: =(résultats!G42-résultats!G161)/résultats!G162 -> -0.62544719 | H38: =(résultats!H42-résultats!H161)/résultats!H162 -> -0.57377748 | I38: =(résultats!I42-résultats!I161)/résultats!I162 -> -0.64619183 | J38: =(résultats!J42-résultats!J161)/résultats!J162 -> -0.58921701 | K38: =(résultats!K42-résultats!K161)/résultats!K162 -> 0.56137675 | L38: =(résultats!L42-résultats!L161)/résultats!L162 -> 0.56793014 | M38: =(résultats!O42-résultats!O161)/résultats!O162 -> -0.4945528 | N38: =(résultats!P42-résultats!P161)/résultats!P162 -> -0.44483396 | O38: =(résultats!Q42-résultats!Q161)/résultats!Q162 -> -0.66451678 | P38: =(résultats!R42-résultats!R161)/résultats!R162 -> -0.59457516 | Q38: =(résultats!S42-résultats!S161)/résultats!S162 -> 0.047621712 | R38: =(résultats!T42-résultats!T161)/résultats!T162 -> 0.10147293 | S38: =(résultats!U42-résultats!U161)/résultats!U162 -> -1.2755554 | T38: =(résultats!V42-résultats!V161)/résultats!V162 -> -1.0597708 | ... Y38: =(résultats!AA42-résultats!AA161)/résultats!AA162 -> -0.56411723 | Z38: - | AA38: - | AB38: - | AD38: =0.865*N38+0.814*P38-0.789*R38 -> -0.94882769
